Workbook
Name empresa_grupo: [1]data!$A$2:$A$1048576
Name Grupo_Ramo: [1]data!$D$2:$D$1048576
Name Periodo: [1]data!$B$2:$B$1048576
Name TIPO_DATO: [1]data!$G$2:$G$1048576

Sheet Instrucciones
B5: INSRUCCIONES PARA LA CUMPLIMENTACIÓN DEL FICHERO MENSUAL DE RECIBOS
C7: Fecha límite para la introducción de recibos: El día 6 del mes siguiente
C8: Fecha límite para enviar fichero: Día 7 de cada mes (o el siguiente laborable)
C10: Requisitos información:
C12: - El periodo siempre es el acumulado del año en curso hasta el último día del mes anterior a la fecha de extracción
C13: - Rellenar la pestaña "Modelo Datos", con la siguiente información:
D14: - Recibos facturados en el periodo
D15: - Recibos anulados en el periodo (los importes de primas y comisiones multiplicar x -1)
C16: (Deberían aparecer todos los recibos anulados en el periodo en curso, incluso si estos recibos se facturaron en años anteriores)
C17: - Revisar en la pestaña "Validación de Datos" que las cifras resultantes de Primas y Comiones son correctas
C18: - Rellenar pestaña otros ingresos: Honorarios y/o otras comisiones. (En caso de recibirlos.)
C19: - En caso de no disponer de algún campo, nos lo tendríais que comunicar
C20: - Cambiar el nombre del fichero a: Nombre Correduria_yyyymm
C21: (Eg: Sabseg_202506)
C22: - Enviar vía email el día 7 a:
D23: carles.saez@sabseg.com
D24: pere.torres@sabseg.com
D25: marc.anadon@sabseg.com

Sheet Descripción
A1: MODELO DATOS | B1: DESCRIPCIÓN
A2: Num. Recibo Cía | B2: Número de recibo compañía
A3: Num. Recibo Interno | B3: Número de recibo interno (El que asigna al programa de gestión)
A4: Núm. Póliza Cía | B4: Número de póliza compañía
A5: Núm. Póliza Interno | B5: Número de póliza interno (El que asigna al programa de gestión)
A6: Fecha facturación | B6: Fecha de Facturación o emisión del recibo
A7: Fecha Efecto | B7: Fecha efecto recibo
A8: Producto | B8: Nombre de Producto
A9: Ramo | B9: Nombre de Ramo (con el mayor desglose posible, no ramo DGS)
A10: Prima neta | B10: Prima neta de póliza (sin impuestos)
A11: Comisión Bruta/Correduria | B11: Es la comsión total percibida, incluye sobrecomisión en recibo (si la hay)
A12: Comisión prima neta | B12: Comsión estándar de la póliza, sin la comsión adicional
A13: Comisión complementaria | B13: Comsión adicional, incluida en recibo
A14: Colaborador 1 | B14: Indicar nombre de Colaborador / Auxiliar Externo Si es una venta Cruzada con otra correduria de Sabseg (póliza que le habeis emitido a la otra correduría), indicar como Colaborador a la otra correduría: "VC NOMBRE CORREDURIA" | K14: Póliza que habeis emitido a la otra correduría
A15: Colaborador 2 | B15: Indicar nombre de Colaborador / Auxiliar Externo Si es una venta Cruzada con otra correduria de Sabseg (póliza que le habeis emitido a la otra correduría), indicar como Colaborador a la otra correduría: "VC NOMBRE CORREDURIA" | K15: Póliza que habeis emitido a la otra correduría
A16: Colaborador 3 | B16: Indicar nombre de Colaborador / Auxiliar Externo Si es una venta Cruzada con otra correduria de Sabseg (póliza que le habeis emitido a la otra correduría), indicar como Colaborador a la otra correduría: "VC NOMBRE CORREDURIA" | K16: Póliza que habeis emitido a la otra correduría
A17: Comisión colaborador 1 | B17: Comisión cedida al colaborador o auxiliar externo
A18: Comisión colaborador 2 | B18: Comisión cedida al colaborador o auxiliar externo
A19: Comisión colaborador 3 | B19: Comisión cedida al colaborador o auxiliar externo
A20: Fecha Liquidación Colaborador | B20: Fecha en las que se liquidan las comisiones al colaborador
A21: Tipo Recibo | B21: - Nueva Producción - Cartera - Sup. Cartera … (Las diferentes tipologías de recibo que tengais en vuestro sistema)
A22: Empresa | B22: Nombre de vuestra correduria
A23: Compañía | B23: Aseguradora de la póliza
A24: Gestión | B24: Tipo de gestión/cobro: - Correduría - Compañía (Los diferentes tipos de gestión/cobro del recibo/póliza que tengais en vuestro sistema)
A25: Duracion póliza | B25: Diferenciar por tipo de póliza. Renovable (Genera cartera) y temporales/únicas (No genera cartera).
A26: Situación | B26: - Cobrado - Liquidado - Pendiente - Anulado …. (Las diferentes situaciones del recibo que tengais en vuestro sistema)
A27: Fecha devolución | B27: Fechas de situación de los recibos
A28: Fecha de liquidación
A29: Fecha de cobro
A30: Fecha anulación
A31: Cliente NIF | B31: NIF del cliente
A32: Cliente Nombre | B32: Nombre del cliente o tomador
A33: Tipo Cliente | B33: Particular / Empresa (o Persona Física / Persona Jurídica)
A34: Cliente CP | B34: Código Postal
A36: OTROS INGRESOS | B36: DESCRIPCIÓN
A37: Honorarios | B37: Honorarios percibidos
A38: Cesiones Honorarios | B38: Cesiones a colaboradores de los honorarios percibidos
A39: Otras comisiones | B39: Otras comisiones percibidas por mediación de seguros (colaborador de otra correduria, que no sea SABSEG.)
A40: Cesiones Otras comisiones | B40: Cesiones a colaboradores de otras comisiones

Sheet Mapeo de Ramos
A1: Empresas | B1: Productos | C1: Ramos | D1: Equivalencia 08/2025 | E1: Agrupación
A2: VEROBROKER | B2: ADMINISTRADORES Y DIRECTIVOS | C2: R. CIVIL | D2: Responsabilidad Civil D&O | E2: Líneas Financieras
A3: VEROBROKER | B3: AHORRO | C3: VIDA | D3: Vida Ahorro Particular | E3: Vida Ahorro Particular
A4: VEROBROKER | B4: AUTOS | C4: AUTOS | D4: Autos Cat. 1 | E4: Autos
A5: VEROBROKER | B5: AVERIA DE MAQUINARIA | C5: OT_DA_MAQ | D5: Averia Maquinaria | E5: Ingeniería
A6: VEROBROKER | B6: CESCE | C6: Caución | D6: Caución | E6: Caución
A7: VEROBROKER | B7: CESCE PORTUGAL | C7: Crédito | D7: Crédito | E7: Crédito
A8: VEROBROKER | B8: COLECTIVO | C8: ACCIDENTES | D8: Accidentes Colectivo | E8: Seguros Personales (No Vida) Colectivos
A9: VEROBROKER | B9: COMBINADOS | C9: AUTOS | D9: Autos Cat. 1 | E9: Autos
A10: VEROBROKER | B10: CONVENIO | C10: ACCIDENTES | D10: Accidentes Convenio | E10: Seguros Personales (No Vida) Colectivos
A11: VEROBROKER | B11: CREDITO | C11: CREDITO | D11: Crédito | E11: Crédito
A12: VEROBROKER | B12: CUADRO MEDICO COLECTIVO | C12: SALUD | D12: Salud Colectivo | E12: Seguros Personales (No Vida) Colectivos
... A32: VEROBROKER | B32: VB CREDITO SOLUNION | C32: Crédito | D32: Crédito | E32: Crédito

Sheet Otros ingresos
A1: INDICAR DETALLE DE OTROS INGRESOS DURANTE EL PERIODO
A2: (Honorarios (SIN IVA), comisiones como colaborador de otras corredurias..)
A4: RAMO | B4: Mes | C4: Honorarios | D4: Cesión Honorarios | E4: Otras comisiones | F4: Cesiones Otras Comsiones | G4: Total

Sheet polizas
A3: Etiquetas de fila | B3: Suma de Prima neta | C3: Suma de Comisión Bruta | D3: Suma de Comisión prima neta
A4: 041095361 | B4: 11978.06 | C4: 1048.08 | D4: 1048.08 | E4: =+VLOOKUP(A4,'Modelo Datos'!C:AJ,4,0) -> 46112 | H4: =+VLOOKUP(A4,'Modelo Datos'!C:AJ,5,0) -> EMBARCACIONES RECREO | I4: =+VLOOKUP(A4,'Modelo Datos'!C:AJ,34,0) -> Embarcaciones | J4: =+VLOOKUP(A4,'Modelo Datos'!C:AJ,32,0) -> Náutica | K4: ALLIANZ | L4: =+VLOOKUP(A4,'Modelo Datos'!C:V,20,0) -> ALLIANZ, COMPAÑIA DE SEGUROS Y REASEGUROS,S.A.
A5: 044963398 | B5: 5520.21 | C5: 552.02 | D5: 552.02 | E5: =+VLOOKUP(A5,'Modelo Datos'!C:AJ,4,0) -> 46037 | H5: =+VLOOKUP(A5,'Modelo Datos'!C:AJ,5,0) -> CONVENIO | I5: =+VLOOKUP(A5,'Modelo Datos'!C:AJ,34,0) -> Accidentes Convenio | J5: =+VLOOKUP(A5,'Modelo Datos'!C:AJ,32,0) -> Seguros Personales (No Vida) Colectivos | K5: ALLIANZ | L5: =+VLOOKUP(A5,'Modelo Datos'!C:V,20,0) -> ALLIANZ, COMPAÑIA DE SEGUROS Y REASEGUROS,S.A.
A6: 045060510 | B6: 219.59 | C6: 21.96 | D6: 21.96 | E6: =+VLOOKUP(A6,'Modelo Datos'!C:AJ,4,0) -> 46054 | H6: =+VLOOKUP(A6,'Modelo Datos'!C:AJ,5,0) -> MULTIRRIESGO OFICINAS | I6: =+VLOOKUP(A6,'Modelo Datos'!C:AJ,34,0) -> Multirriesgo Ofinas y Despachos | J6: =+VLOOKUP(A6,'Modelo Datos'!C:AJ,32,0) -> Property | K6: ALLIANZ | L6: =+VLOOKUP(A6,'Modelo Datos'!C:V,20,0) -> ALLIANZ, COMPAÑIA DE SEGUROS Y REASEGUROS,S.A.
A7: 189001045 | B7: 1534.91 | C7: 115.12 | D7: 115.12 | E7: =+VLOOKUP(A7,'Modelo Datos'!C:AJ,4,0) -> 46023 | H7: =+VLOOKUP(A7,'Modelo Datos'!C:AJ,5,0) -> AHORRO | I7: =+VLOOKUP(A7,'Modelo Datos'!C:AJ,34,0) -> Vida Ahorro Particular | J7: =+VLOOKUP(A7,'Modelo Datos'!C:AJ,32,0) -> Vida Ahorro Particular | K7: ZURICH | L7: =+VLOOKUP(A7,'Modelo Datos'!C:V,20,0) -> ZURICH VIDA, CIA. DE SEGUROS Y REASEGUROS,S.A.
A8: 2002300647614 | B8: 826.82 | C8: 57.88 | D8: 57.88 | E8: =+VLOOKUP(A8,'Modelo Datos'!C:AJ,4,0) -> 46023 | H8: =+VLOOKUP(A8,'Modelo Datos'!C:AJ,5,0) -> TODO RIESGO | I8: =+VLOOKUP(A8,'Modelo Datos'!C:AJ,34,0) -> Autos Cat. 1 | J8: =+VLOOKUP(A8,'Modelo Datos'!C:AJ,32,0) -> Autos | K8: MAPFRE | L8: =+VLOOKUP(A8,'Modelo Datos'!C:V,20,0) -> MAPFRE ESPAÑA, CIA. DE SEG. Y REASEG.,S.A.
A9: 20190120167898 | B9: 3444.73 | C9: 344.48 | D9: 344.48 | E9: =+VLOOKUP(A9,'Modelo Datos'!C:AJ,4,0) -> 46023 | H9: =+VLOOKUP(A9,'Modelo Datos'!C:AJ,5,0) -> RIESGO | I9: =+VLOOKUP(A9,'Modelo Datos'!C:AJ,34,0) -> Vida Riesgo Particular | J9: =+VLOOKUP(A9,'Modelo Datos'!C:AJ,32,0) -> Vida Riesgo Particular | K9: SVRNE | L9: =+VLOOKUP(A9,'Modelo Datos'!C:V,20,0) -> SURNE, MUTUA DE SEG. Y REAS. A PRIMA FIJA
A10: 205124739 | B10: 526.4 | C10: 24.76 | D10: 24.76 | E10: =+VLOOKUP(A10,'Modelo Datos'!C:AJ,4,0) -> 45992 | H10: =+VLOOKUP(A10,'Modelo Datos'!C:AJ,5,0) -> CONVENIO | I10: =+VLOOKUP(A10,'Modelo Datos'!C:AJ,34,0) -> Accidentes Convenio | J10: =+VLOOKUP(A10,'Modelo Datos'!C:AJ,32,0) -> Seguros Personales (No Vida) Colectivos | K10: ALLIANZ | L10: =+VLOOKUP(A10,'Modelo Datos'!C:V,20,0) -> ALLIANZ PORTUGAL
A11: 205201332 | B11: 1214.94 | C11: 51.64 | D11: 51.64 | E11: =+VLOOKUP(A11,'Modelo Datos'!C:AJ,4,0) -> 46023 | H11: =+VLOOKUP(A11,'Modelo Datos'!C:AJ,5,0) -> CUADRO MEDICO INDIVIDUAL | I11: =+VLOOKUP(A11,'Modelo Datos'!C:AJ,34,0) -> Salud Particular | J11: =+VLOOKUP(A11,'Modelo Datos'!C:AJ,32,0) -> Seguros Personales (No Vida) Particular | K11: ALLIANZ | L11: =+VLOOKUP(A11,'Modelo Datos'!C:V,20,0) -> ALLIANZ PORTUGAL
A12: 205228708 | B12: 495.22 | C12: 23.7 | D12: 23.7 | E12: =+VLOOKUP(A12,'Modelo Datos'!C:AJ,4,0) -> 45992 | H12: =+VLOOKUP(A12,'Modelo Datos'!C:AJ,5,0) -> CUADRO MEDICO INDIVIDUAL | I12: =+VLOOKUP(A12,'Modelo Datos'!C:AJ,34,0) -> Salud Particular | J12: =+VLOOKUP(A12,'Modelo Datos'!C:AJ,32,0) -> Seguros Personales (No Vida) Particular | K12: ALLIANZ | L12: =+VLOOKUP(A12,'Modelo Datos'!C:V,20,0) -> ALLIANZ PORTUGAL
A13: 205303370 | B13: 616.28 | C13: 30.8 | D13: 30.8 | E13: =+VLOOKUP(A13,'Modelo Datos'!C:AJ,4,0) -> 45992 | H13: =+VLOOKUP(A13,'Modelo Datos'!C:AJ,5,0) -> CUADRO MEDICO INDIVIDUAL | I13: =+VLOOKUP(A13,'Modelo Datos'!C:AJ,34,0) -> Salud Particular | J13: =+VLOOKUP(A13,'Modelo Datos'!C:AJ,32,0) -> Seguros Personales (No Vida) Particular | K13: ALLIANZ | L13: =+VLOOKUP(A13,'Modelo Datos'!C:V,20,0) -> ALLIANZ PORTUGAL
A14: 271005337647 | B14: 13855.52 | C14: 346.4 | D14: 346.4 | E14: =+VLOOKUP(A14,'Modelo Datos'!C:AJ,4,0) -> 46023 | H14: =+VLOOKUP(A14,'Modelo Datos'!C:AJ,5,0) -> CUADRO MEDICO INDIVIDUAL | I14: =+VLOOKUP(A14,'Modelo Datos'!C:AJ,34,0) -> Salud Particular | J14: =+VLOOKUP(A14,'Modelo Datos'!C:AJ,32,0) -> Seguros Personales (No Vida) Particular | K14: MAPFRE | L14: =+VLOOKUP(A14,'Modelo Datos'!C:V,20,0) -> MAPFRE ESPAÑA, CIA. DE SEG. Y REASEG.,S.A.
A15: 40005230 | B15: 2277.94 | C15: 227.8 | D15: 227.8 | E15: =+VLOOKUP(A15,'Modelo Datos'!C:AJ,4,0) -> 46012 | H15: =+VLOOKUP(A15,'Modelo Datos'!C:AJ,5,0) -> PROTECCION E INDEMIZACION | I15: =+VLOOKUP(A15,'Modelo Datos'!C:AJ,34,0) -> Transportes Mercancías | J15: =+VLOOKUP(A15,'Modelo Datos'!C:AJ,32,0) -> Transporte | K15: MS AMLIN | L15: =+VLOOKUP(A15,'Modelo Datos'!C:V,20,0) -> MS AMLIN MARINE N.V.
... A38: SP030-001981-25 | B38: 56879.98 | C38: 5688 | D38: 5688 | E38: =+VLOOKUP(A38,'Modelo Datos'!C:AJ,4,0) -> 45951 | H38: =+VLOOKUP(A38,'Modelo Datos'!C:AJ,5,0) -> MERCANCIAS | I38: =+VLOOKUP(A38,'Modelo Datos'!C:AJ,34,0) -> Transportes Mercancías | J38: =+VLOOKUP(A38,'Modelo Datos'!C:AJ,32,0) -> Transporte | K38: RSA | L38: =+VLOOKUP(A38,'Modelo Datos'!C:V,20,0) -> RSA LUXEMBURGO, S.A. SUC. EN ESPAÑA
A39: Total general | B39: 287153.66 | C39: 26781.44 | D39: 26781.44 | E39: =+VLOOKUP(A39,'Modelo Datos'!C:AJ,4,0) -> #N/A

Sheet Modelo Datos
A1: Num. Recibo Cía | B1: Núm. Recibo Interno | C1: Núm. Póliza Cía | D1: Núm. Póliza Interno | E1: Fecha facturación | F1: Fecha Efecto | G1: Producto | H1: Ramo | I1: Prima neta | J1: Comisión Bruta | K1: Comisión prima neta | L1: Comisión complementaria | M1: Colaborador 1 | N1: Colaborador 2 | O1: Colaborador 3 | P1: Comisión colaborador 1 | Q1: Comisión colaborador 2 | R1: Comisión colaborador 3 | S1: Fecha Liquidación Colaborador | T1: Tipo Recibo | U1: Empresa | V1: Compañía | W1: Gestión | X1: Duracion póliza | Y1: Situación | Z1: Fecha devolución | AA1: Fecha de liquidación | AB1: Fecha de cobro | AC1: Fecha anulación | AD1: Cliente NIF | AE1: Cliente Nombre | AF1: Tipo Cliente | AG1: Cliente CP | AH1: agrupacion | AI1: mes | AJ1: ramo
A2: 2728330 | B2: 5002690000 | C2: 20190120167898 | E2: 46024 | F2: 46023 | G2: RIESGO | H2: VI_RIESGO | I2: 3444.73 | J2: 344.48 | K2: 344.48 | U2: VEROBROKER | V2: SURNE, MUTUA DE SEG. Y REAS. A PRIMA FIJA | W2: AK_DIRCIA | Y2: Facturado | AE2: IBER STEEL, S.L. | AH2: =+VLOOKUP(G2,'Mapeo de Ramos'!B:E,4,0) -> Vida Riesgo Particular | AJ2: =+VLOOKUP(G2,'Mapeo de Ramos'!B:D,3,0) -> Vida Riesgo Particular
A3: 568458693 | B3: 5002689485 | C3: 044963398 | E3: 46024 | F3: 46037 | G3: CONVENIO | H3: ACCIDENTES | I3: 5520.21 | J3: 552.02 | K3: 552.02 | U3: VEROBROKER | V3: ALLIANZ, COMPAÑIA DE SEGUROS Y REASEGUROS,S.A. | W3: AK_BANCO | Y3: Liquid. | AA3: 46034 | AE3: LEON COATED SOLUTIONS, S.L. | AH3: =+VLOOKUP(G3,'Mapeo de Ramos'!B:E,4,0) -> Seguros Personales (No Vida) Colectivos | AJ3: =+VLOOKUP(G3,'Mapeo de Ramos'!B:D,3,0) -> Accidentes Convenio
A4: 582497826 | B4: 5002699648 | C4: 205201332 | E4: 46024 | F4: 46023 | G4: CUADRO MEDICO INDIVIDUAL | H4: ASIST_SANI | I4: 607.47 | J4: 25.82 | K4: 25.82 | U4: VEROBROKER | V4: ALLIANZ PORTUGAL | W4: AK_DIRCIA | Y4: Liquid. | AA4: 46057 | AE4: PLANOS FERRICOS PORTUGAL PRODUCTOS SIDERÚRGICOS LD | AH4: =+VLOOKUP(G4,'Mapeo de Ramos'!B:E,4,0) -> Seguros Personales (No Vida) Particular | AJ4: =+VLOOKUP(G4,'Mapeo de Ramos'!B:D,3,0) -> Salud Particular
A5: 8732115179 | B5: 5002692228 | C5: 2002300647614 | E5: 46024 | F5: 46023 | G5: TODO RIESGO | H5: AUTOS | I5: 826.82 | J5: 57.88 | K5: 57.88 | U5: VEROBROKER | V5: MAPFRE ESPAÑA, CIA. DE SEG. Y REASEG.,S.A. | W5: AK_DIRCIA | Y5: Cobrado | AA5: 46021 | AE5: ARANDA COATED SOLUTIONS, S.L | AH5: =+VLOOKUP(G5,'Mapeo de Ramos'!B:E,4,0) -> Autos | AJ5: =+VLOOKUP(G5,'Mapeo de Ramos'!B:D,3,0) -> Autos Cat. 1
A6: 25123736 | B6: 5002730989 | C6: 40005230 | E6: 46029 | F6: 46012 | G6: PROTECCION E INDEMIZACION | H6: TRANSPORTE | I6: 1143.8 | J6: 114.38 | K6: 114.38 | U6: VEROBROKER | V6: MS AMLIN MARINE N.V. | W6: AK_CORRED | Y6: Facturado | AE6: NETWORK STEEL, S.L. | AH6: =+VLOOKUP(G6,'Mapeo de Ramos'!B:E,4,0) -> Transporte | AJ6: =+VLOOKUP(G6,'Mapeo de Ramos'!B:D,3,0) -> Transportes Mercancías
A7: 020122012025012A | B7: 5002732508 | C7: 82774870-0 | E7: 46029 | F7: 45992 | G7: SALUD COLECTIVO | H7: ASIST_SANI | I7: 1796.85 | J7: 73.5 | K7: 73.5 | U7: VEROBROKER | V7: SANITAS, S.A. DE SEGUROS | W7: AK_DIRCIA | Y7: Liquid. | AA7: 46029 | AE7: NETWORK STEEL RESOURCES, S.A | AH7: =+VLOOKUP(G7,'Mapeo de Ramos'!B:E,4,0) -> Seguros Personales (No Vida) Colectivos | AJ7: =+VLOOKUP(G7,'Mapeo de Ramos'!B:D,3,0) -> Salud Colectivo
A8: 020122012025012A | B8: 5002732493 | C8: 82774870-1 | E8: 46029 | F8: 45992 | G8: SALUD COLECTIVO | H8: ASIST_SANI | I8: 798.6 | J8: 31.92 | K8: 31.92 | U8: VEROBROKER | V8: SANITAS, S.A. DE SEGUROS | W8: AK_DIRCIA | Y8: Liquid. | AA8: 46029 | AE8: NETWORK STEEL, S.L. | AH8: =+VLOOKUP(G8,'Mapeo de Ramos'!B:E,4,0) -> Seguros Personales (No Vida) Colectivos | AJ8: =+VLOOKUP(G8,'Mapeo de Ramos'!B:D,3,0) -> Salud Colectivo
A9: 020122012025012A | B9: 5002732500 | C9: 82774870-11 | E9: 46029 | F9: 45992 | G9: SALUD COLECTIVO | H9: ASIST_SANI | I9: 132.05 | J9: 5.28 | K9: 5.28 | U9: VEROBROKER | V9: SANITAS, S.A. DE SEGUROS | W9: AK_DIRCIA | Y9: Liquid. | AA9: 46029 | AE9: NETWORK STEEL, S.L. | AH9: =+VLOOKUP(G9,'Mapeo de Ramos'!B:E,4,0) -> Seguros Personales (No Vida) Colectivos | AJ9: =+VLOOKUP(G9,'Mapeo de Ramos'!B:D,3,0) -> Salud Colectivo
A10: 020122012025012A | B10: 5002732504 | C10: 82774870-12 | E10: 46029 | F10: 45992 | G10: SALUD COLECTIVO | H10: ASIST_SANI | I10: 265.5 | J10: 10.94 | K10: 10.94 | U10: VEROBROKER | V10: SANITAS, S.A. DE SEGUROS | W10: AK_DIRCIA | Y10: Liquid. | AA10: 46029 | AE10: NETWORK STEEL RESOURCES, S.A | AH10: =+VLOOKUP(G10,'Mapeo de Ramos'!B:E,4,0) -> Seguros Personales (No Vida) Colectivos | AJ10: =+VLOOKUP(G10,'Mapeo de Ramos'!B:D,3,0) -> Salud Colectivo
A11: 020122012025012A | B11: 5002732506 | C11: 82774870-13 | E11: 46029 | F11: 45992 | G11: SALUD COLECTIVO | H11: ASIST_SANI | I11: 1397.55 | J11: 57.2 | K11: 57.2 | U11: VEROBROKER | V11: SANITAS, S.A. DE SEGUROS | W11: AK_DIRCIA | Y11: Liquid. | AA11: 46029 | AE11: LEON COATED SOLUTIONS, S.L. | AH11: =+VLOOKUP(G11,'Mapeo de Ramos'!B:E,4,0) -> Seguros Personales (No Vida) Colectivos | AJ11: =+VLOOKUP(G11,'Mapeo de Ramos'!B:D,3,0) -> Salud Colectivo
A12: 020122012025012A | B12: 5002732494 | C12: 82774870-15 | E12: 46029 | F12: 45992 | G12: SALUD COLECTIVO | H12: ASIST_SANI | I12: 199.65 | J12: 7.98 | K12: 7.98 | U12: VEROBROKER | V12: SANITAS, S.A. DE SEGUROS | W12: AK_DIRCIA | Y12: Liquid. | AA12: 46029 | AE12: NETWORK STEEL AFRICA S.L. | AH12: =+VLOOKUP(G12,'Mapeo de Ramos'!B:E,4,0) -> Seguros Personales (No Vida) Colectivos | AJ12: =+VLOOKUP(G12,'Mapeo de Ramos'!B:D,3,0) -> Salud Colectivo
A13: 020122012025012A | B13: 5002732498 | C13: 82774870-16 | E13: 46029 | F13: 45992 | G13: SALUD COLECTIVO | H13: ASIST_SANI | I13: 66.55 | J13: 3 | K13: 3 | U13: VEROBROKER | V13: SANITAS, S.A. DE SEGUROS | W13: AK_DIRCIA | Y13: Liquid. | AA13: 46029 | AE13: ACEROS RECUBIERTOS IMPORTACION MEDITERRA | AH13: =+VLOOKUP(G13,'Mapeo de Ramos'!B:E,4,0) -> Seguros Personales (No Vida) Colectivos | AJ13: =+VLOOKUP(G13,'Mapeo de Ramos'!B:D,3,0) -> Salud Colectivo
A14: 020122012025012A | B14: 5002732502 | C14: 82774870-19 | E14: 46029 | F14: 45992 | G14: CUADRO MEDICO COLECTIVO | H14: ASIST_SANI | I14: 318.81 | J14: 12.75 | K14: 12.75 | U14: VEROBROKER | V14: SANITAS, S.A. DE SEGUROS | W14: AK_DIRCIA | Y14: Liquid. | AA14: 46029 | AE14: PLANOS FERRICOS SLU | AH14: =+VLOOKUP(G14,'Mapeo de Ramos'!B:E,4,0) -> Seguros Personales (No Vida) Colectivos | AJ14: =+VLOOKUP(G14,'Mapeo de Ramos'!B:D,3,0) -> Salud Colectivo
A15: 020122012025012A | B15: 5002732496 | C15: 82774870-2 | E15: 46029 | F15: 45992 | G15: SALUD COLECTIVO | H15: ASIST_SANI | I15: 266.2 | J15: 10.64 | K15: 10.64 | U15: VEROBROKER | V15: SANITAS, S.A. DE SEGUROS | W15: AK_DIRCIA | Y15: Liquid. | AA15: 46029 | AE15: SANTANDER COATED SOLUTIONS, S.L. | AH15: =+VLOOKUP(G15,'Mapeo de Ramos'!B:E,4,0) -> Seguros Personales (No Vida) Colectivos | AJ15: =+VLOOKUP(G15,'Mapeo de Ramos'!B:D,3,0) -> Salud Colectivo
A16: 020122012025012A | B16: 5002732495 | C16: 82774870-3 | E16: 46029 | F16: 45992 | G16: SALUD COLECTIVO | H16: ASIST_SANI | I16: 553.87 | J16: 22.48 | K16: 22.48 | U16: VEROBROKER | V16: SANITAS, S.A. DE SEGUROS | W16: AK_DIRCIA | Y16: Liquid. | AA16: 46029 | AE16: ECO STEEL SOLUTIONS S.L. | AH16: =+VLOOKUP(G16,'Mapeo de Ramos'!B:E,4,0) -> Seguros Personales (No Vida) Colectivos | AJ16: =+VLOOKUP(G16,'Mapeo de Ramos'!B:D,3,0) -> Salud Colectivo
A17: 020122012025012A | B17: 5002732499 | C17: 82774870-4 | E17: 46029 | F17: 45992 | G17: SALUD COLECTIVO | H17: ASIST_SANI | I17: 931.7 | J17: 37.24 | K17: 37.24 | U17: VEROBROKER | V17: SANITAS, S.A. DE SEGUROS | W17: AK_DIRCIA | Y17: Liquid. | AA17: 46029 | AE17: ARANDA COATED SOLUTIONS, S.L | AH17: =+VLOOKUP(G17,'Mapeo de Ramos'!B:E,4,0) -> Seguros Personales (No Vida) Colectivos | AJ17: =+VLOOKUP(G17,'Mapeo de Ramos'!B:D,3,0) -> Salud Colectivo
A18: 020122012025012A | B18: 5002732507 | C18: 82774870-5 | E18: 46029 | F18: 45992 | G18: SALUD COLECTIVO | H18: ASIST_SANI | I18: 1264.45 | J18: 51.21 | K18: 51.21 | U18: VEROBROKER | V18: SANITAS, S.A. DE SEGUROS | W18: AK_DIRCIA | Y18: Liquid. | AA18: 46029 | AE18: PLANOS FERRICOS SLU | AH18: =+VLOOKUP(G18,'Mapeo de Ramos'!B:E,4,0) -> Seguros Personales (No Vida) Colectivos | AJ18: =+VLOOKUP(G18,'Mapeo de Ramos'!B:D,3,0) -> Salud Colectivo
... A21: 020122012025012A | B21: 5002732501 | C21: 82774870-9 | E21: 46029 | F21: 45992 | G21: SALUD COLECTIVO | H21: ASIST_SANI | I21: 106.27 | J21: 4.25 | K21: 4.25 | U21: VEROBROKER | V21: SANITAS, S.A. DE SEGUROS | W21: AK_DIRCIA | Y21: Liquid. | AA21: 46029 | AE21: SANTANDER COATED SOLUTIONS, S.L. | AH21: =+VLOOKUP(G21,'Mapeo de Ramos'!B:E,4,0) -> Seguros Personales (No Vida) Colectivos | AJ21: =+VLOOKUP(G21,'Mapeo de Ramos'!B:D,3,0) -> Salud Colectivo
A22: 1514126F01 | B22: 5002727674 | C22: SP030-001084-25 | E22: 46029 | F22: 45989 | G22: MERCANCIAS | H22: TRANSPORTE | I22: 12259.18 | J22: 1225.92 | K22: 1225.92 | U22: VEROBROKER | V22: RSA LUXEMBURGO, S.A. SUC. EN ESPAÑA | W22: AK_CORRED | Y22: Facturado | AE22: SANTANDER COATED SOLUTIONS, S.L. | AH22: =+VLOOKUP(G22,'Mapeo de Ramos'!B:E,4,0) -> Transporte | AJ22: =+VLOOKUP(G22,'Mapeo de Ramos'!B:D,3,0) -> Transportes Mercancías
A23: 52772156 | B23: 5002733042 | C23: 189001045 | E23: 46030 | F23: 46023 | G23: AHORRO | H23: VI_AHORRO | I23: 1534.91 | J23: 115.12 | K23: 115.12 | U23: VEROBROKER | V23: ZURICH VIDA, CIA. DE SEGUROS Y REASEGUROS,S.A. | W23: AK_DIRCIA | Y23: Liquid. | AA23: 46030 | AE23: ECO STEEL SOLUTIONS S.L. | AH23: =+VLOOKUP(G23,'Mapeo de Ramos'!B:E,4,0) -> Vida Ahorro Particular | AJ23: =+VLOOKUP(G23,'Mapeo de Ramos'!B:D,3,0) -> Vida Ahorro Particular
A24: 8764786996 | B24: 5002738892 | C24: 271005337647 | E24: 46030 | F24: 46023 | G24: CUADRO MEDICO INDIVIDUAL | H24: ASIST_SANI | I24: 13855.52 | J24: 346.4 | K24: 346.4 | U24: VEROBROKER | V24: MAPFRE ESPAÑA, CIA. DE SEG. Y REASEG.,S.A. | W24: AK_DIRCIA | Y24: Cobrado | AA24: 46057 | AE24: NETWORK STEEL RESOURCES, S.A | AH24: =+VLOOKUP(G24,'Mapeo de Ramos'!B:E,4,0) -> Seguros Personales (No Vida) Particular | AJ24: =+VLOOKUP(G24,'Mapeo de Ramos'!B:D,3,0) -> Salud Particular
A25: 1516169F01 | B25: 5002732679 | C25: SP030-000699-25 | E25: 46030 | F25: 45929 | G25: MERCANCIAS | H25: TRANSPORTE | I25: 87.37 | J25: 8.74 | K25: 8.74 | U25: VEROBROKER | V25: RSA LUXEMBURGO, S.A. SUC. EN ESPAÑA | W25: AK_CORRED | Y25: Facturado | AE25: NETWORK STEEL, S.L. | AH25: =+VLOOKUP(G25,'Mapeo de Ramos'!B:E,4,0) -> Transporte | AJ25: =+VLOOKUP(G25,'Mapeo de Ramos'!B:D,3,0) -> Transportes Mercancías
A26: 1516577F01 | B26: 5002732701 | C26: SP030-001874-25 | E26: 46030 | F26: 46004 | G26: MERCANCIAS | H26: TRANSPORTE | I26: 10842.12 | J26: 1084.21 | K26: 1084.21 | U26: VEROBROKER | V26: RSA LUXEMBURGO, S.A. SUC. EN ESPAÑA | W26: AK_CORRED | Y26: Facturado | AE26: AVEIRO COATED SOLUTIONS | AH26: =+VLOOKUP(G26,'Mapeo de Ramos'!B:E,4,0) -> Transporte | AJ26: =+VLOOKUP(G26,'Mapeo de Ramos'!B:D,3,0) -> Transportes Mercancías
A27: 546215 | B27: 5002739069 | C27: SP030-000699-25 | E27: 46031 | F27: 45951 | G27: MERCANCIAS | H27: TRANSPORTE | I27: 9341.94 | J27: 934.2 | K27: 934.2 | U27: VEROBROKER | V27: RSA LUXEMBURGO, S.A. SUC. EN ESPAÑA | W27: AK_CORRED | Y27: Facturado | AE27: NETWORK STEEL, S.L. | AH27: =+VLOOKUP(G27,'Mapeo de Ramos'!B:E,4,0) -> Transporte | AJ27: =+VLOOKUP(G27,'Mapeo de Ramos'!B:D,3,0) -> Transportes Mercancías
A28: 574622506 | B28: 5002743242 | C28: 205228708 | E28: 46031 | F28: 45992 | G28: CUADRO MEDICO INDIVIDUAL | H28: ASIST_SANI | I28: 242.02 | J28: 12.1 | K28: 12.1 | U28: VEROBROKER | V28: ALLIANZ PORTUGAL | W28: AK_DIRCIA | Y28: Liquid. | AA28: 46031 | AE28: PLANOS FERRICOS PORTUGAL PRODUCTOS SIDERÚRGICOS LD | AH28: =+VLOOKUP(G28,'Mapeo de Ramos'!B:E,4,0) -> Seguros Personales (No Vida) Particular | AJ28: =+VLOOKUP(G28,'Mapeo de Ramos'!B:D,3,0) -> Salud Particular
A29: 574640904 | B29: 5002743243 | C29: 205303370 | E29: 46031 | F29: 45992 | G29: CUADRO MEDICO INDIVIDUAL | H29: ASIST_SANI | I29: 308.14 | J29: 15.4 | K29: 15.4 | U29: VEROBROKER | V29: ALLIANZ PORTUGAL | W29: AK_DIRCIA | Y29: Liquid. | AA29: 46031 | AE29: PLANOS FERRICOS PORTUGAL PRODUCTOS SIDERÚRGICOS LD | AH29: =+VLOOKUP(G29,'Mapeo de Ramos'!B:E,4,0) -> Seguros Personales (No Vida) Particular | AJ29: =+VLOOKUP(G29,'Mapeo de Ramos'!B:D,3,0) -> Salud Particular
A30: 576539096 | B30: 5002743241 | C30: 205124739 | E30: 46031 | F30: 45992 | G30: CONVENIO | H30: ACCIDENTES | I30: 526.4 | J30: 24.76 | K30: 24.76 | U30: VEROBROKER | V30: ALLIANZ PORTUGAL | W30: AK_DIRCIA | Y30: Liquid. | AA30: 46031 | AE30: PLANOS FERRICOS PORTUGAL PRODUCTOS SIDERÚRGICOS LD | AH30: =+VLOOKUP(G30,'Mapeo de Ramos'!B:E,4,0) -> Seguros Personales (No Vida) Colectivos | AJ30: =+VLOOKUP(G30,'Mapeo de Ramos'!B:D,3,0) -> Accidentes Convenio
A31: 1516629F01 | B31: 5002739067 | C31: SP030-000699-25 | E31: 46031 | F31: 46001 | G31: MERCANCIAS | H31: TRANSPORTE | I31: 47102.55 | J31: 4710.26 | K31: 4710.26 | U31: VEROBROKER | V31: RSA LUXEMBURGO, S.A. SUC. EN ESPAÑA | W31: AK_CORRED | Y31: Facturado | AE31: NETWORK STEEL, S.L. | AH31: =+VLOOKUP(G31,'Mapeo de Ramos'!B:E,4,0) -> Transporte | AJ31: =+VLOOKUP(G31,'Mapeo de Ramos'!B:D,3,0) -> Transportes Mercancías
A32: 1516703F01 | B32: 5002739073 | C32: SP030-001981-25 | E32: 46031 | F32: 45951 | G32: MERCANCIAS | H32: TRANSPORTE | I32: 33471.12 | J32: 3347.11 | K32: 3347.11 | U32: VEROBROKER | V32: RSA LUXEMBURGO, S.A. SUC. EN ESPAÑA | W32: AK_CORRED | Y32: Facturado | AE32: LEON COATED SOLUTIONS, S.L. | AH32: =+VLOOKUP(G32,'Mapeo de Ramos'!B:E,4,0) -> Transporte | AJ32: =+VLOOKUP(G32,'Mapeo de Ramos'!B:D,3,0) -> Transportes Mercancías
A33: 1519702F01 | B33: 5002748787 | C33: SP030-001084-25 | E33: 46042 | F33: 45972 | G33: MERCANCIAS | H33: TRANSPORTE | I33: 7025.13 | J33: 702.52 | K33: 702.52 | U33: VEROBROKER | V33: RSA LUXEMBURGO, S.A. SUC. EN ESPAÑA | W33: AK_CORRED | Y33: Facturado | AE33: SANTANDER COATED SOLUTIONS, S.L. | AH33: =+VLOOKUP(G33,'Mapeo de Ramos'!B:E,4,0) -> Transporte | AJ33: =+VLOOKUP(G33,'Mapeo de Ramos'!B:D,3,0) -> Transportes Mercancías
A34: 1519756F01 | B34: 5002748788 | C34: SP030-000699-25 | E34: 46042 | F34: 45972 | G34: MERCANCIAS | H34: TRANSPORTE | I34: 916.37 | J34: 91.64 | K34: 91.64 | U34: VEROBROKER | V34: RSA LUXEMBURGO, S.A. SUC. EN ESPAÑA | W34: AK_CORRED | Y34: Facturado | AE34: NETWORK STEEL, S.L. | AH34: =+VLOOKUP(G34,'Mapeo de Ramos'!B:E,4,0) -> Transporte | AJ34: =+VLOOKUP(G34,'Mapeo de Ramos'!B:D,3,0) -> Transportes Mercancías
A35: 1520919F01 | B35: 5002749058 | C35: SP030-001084-25 | E35: 46043 | F35: 45929 | G35: MERCANCIAS | H35: TRANSPORTE | I35: 12712.99 | J35: 1271.3 | K35: 1271.3 | U35: VEROBROKER | V35: RSA LUXEMBURGO, S.A. SUC. EN ESPAÑA | W35: AK_CORRED | Y35: Facturado | AE35: SANTANDER COATED SOLUTIONS, S.L. | AH35: =+VLOOKUP(G35,'Mapeo de Ramos'!B:E,4,0) -> Transporte | AJ35: =+VLOOKUP(G35,'Mapeo de Ramos'!B:D,3,0) -> Transportes Mercancías
A36: 1521105F01 | B36: 5002749076 | C36: SP030-001874-25 | E36: 46043 | F36: 45994 | G36: MERCANCIAS | H36: TRANSPORTE | I36: 324.36 | J36: 32.44 | K36: 32.44 | U36: VEROBROKER | V36: RSA LUXEMBURGO, S.A. SUC. EN ESPAÑA | W36: AK_CORRED | Y36: Facturado | AE36: AVEIRO COATED SOLUTIONS | AH36: =+VLOOKUP(G36,'Mapeo de Ramos'!B:E,4,0) -> Transporte | AJ36: =+VLOOKUP(G36,'Mapeo de Ramos'!B:D,3,0) -> Transportes Mercancías
A37: 580199507 | B37: 5002765613 | C37: 205228708 | E37: 46057 | F37: 46023 | G37: CUADRO MEDICO INDIVIDUAL | H37: ASIST_SANI | I37: 253.2 | J37: 11.6 | K37: 11.6 | U37: VEROBROKER | V37: ALLIANZ PORTUGAL | Y37: Liquid. | AE37: PLANOS FERRICOS PORTUGAL PRODUCTOS SIDERÚRGICOS LD | AH37: =+VLOOKUP(G37,'Mapeo de Ramos'!B:E,4,0) -> Seguros Personales (No Vida) Particular | AJ37: =+VLOOKUP(G37,'Mapeo de Ramos'!B:D,3,0) -> Salud Particular
A38: 588191837 | B38: 5002755771 | C38: 205201332 | E38: 46055 | F38: 46054 | G38: CUADRO MEDICO INDIVIDUAL | H38: ASIST_SANI | I38: 607.47 | J38: 25.82 | K38: 25.82 | U38: VEROBROKER | V38: ALLIANZ PORTUGAL | Y38: Liquid. | AE38: PLANOS FERRICOS PORTUGAL PRODUCTOS SIDERÚRGICOS LD | AH38: =+VLOOKUP(G38,'Mapeo de Ramos'!B:E,4,0) -> Seguros Personales (No Vida) Particular | AJ38: =+VLOOKUP(G38,'Mapeo de Ramos'!B:D,3,0) -> Salud Particular
A39: 580220485 | B39: 5002765614 | C39: 205303370 | E39: 46057 | F39: 46023 | G39: CUADRO MEDICO INDIVIDUAL | H39: ASIST_SANI | I39: 308.14 | J39: 15.4 | K39: 15.4 | U39: VEROBROKER | V39: ALLIANZ PORTUGAL | Y39: Liquid. | AE39: PLANOS FERRICOS PORTUGAL PRODUCTOS SIDERÚRGICOS LD | AH39: =+VLOOKUP(G39,'Mapeo de Ramos'!B:E,4,0) -> Seguros Personales (No Vida) Particular | AJ39: =+VLOOKUP(G39,'Mapeo de Ramos'!B:D,3,0) -> Salud Particular
A40: 585998010 | B40: 5002769864 | C40: 041095361 | E40: 46062 | F40: 46112 | G40: EMBARCACIONES RECREO | H40: TRANSPORTE | I40: 11978.06 | J40: 1048.08 | K40: 1048.08 | U40: VEROBROKER | V40: ALLIANZ, COMPAÑIA DE SEGUROS Y REASEGUROS,S.A. | Y40: Anulado | AE40: ACEROS RECUBIERTOS IMPORTACION MEDITERRA | AH40: =+VLOOKUP(G40,'Mapeo de Ramos'!B:E,4,0) -> Náutica | AJ40: =+VLOOKUP(G40,'Mapeo de Ramos'!B:D,3,0) -> Embarcaciones
A41: 571886534 | B41: 5002753050 | C41: 045060510 | E41: 46055 | F41: 46054 | G41: MULTIRRIESGO OFICINAS | H41: MULT_COMER | I41: 219.59 | J41: 21.96 | K41: 21.96 | U41: VEROBROKER | V41: ALLIANZ, COMPAÑIA DE SEGUROS Y REASEGUROS,S.A. | Y41: Liquid. | AE41: NETWORK STEEL AFRICA S.L. | AH41: =+VLOOKUP(G41,'Mapeo de Ramos'!B:E,4,0) -> Property | AJ41: =+VLOOKUP(G41,'Mapeo de Ramos'!B:D,3,0) -> Multirriesgo Ofinas y Despachos
A42: 26020827 | B42: 5002769198 | C42: 40005230 | E42: 46059 | F42: 46043 | G42: PROTECCION E INDEMIZACION | H42: TRANSPORTE | I42: 1134.14 | J42: 113.42 | K42: 113.42 | U42: VEROBROKER | V42: MS AMLIN MARINE N.V. | Y42: Facturado | AE42: NETWORK STEEL, S.L. | AH42: =+VLOOKUP(G42,'Mapeo de Ramos'!B:E,4,0) -> Transporte | AJ42: =+VLOOKUP(G42,'Mapeo de Ramos'!B:D,3,0) -> Transportes Mercancías
...

Sheet TD
A1: Situación | B1: (Varios elementos) | F1: €' 000 | G1: Prima neta YTD R | H1: Comisiones Brutas YTD R | I1: cesiones
F2: Caución
A3: Etiquetas de fila | B3: Suma de Prima neta | C3: Suma de Comisión Bruta | F3: Crédito
A4: Autos | B4: 826.82 | C4: 57.88 | F4: Empresas
A5: Property | B5: 219.59 | C5: 21.96 | F5: Flotas
A6: Seguros Personales (No Vida) Colectivos | B6: 14918.6 | C6: 936.45 | F6: Ingeniería
A7: Seguros Personales (No Vida) Particular | B7: 16181.96 | C7: 452.54 | F7: Líneas Financieras
A8: Transporte | B8: 238048.99 | C8: 23804.93 | F8: Property
A9: Vida Ahorro Particular | B9: 1534.91 | C9: 115.12 | F9: Responsabilidad Civil
A10: Vida Riesgo Particular | B10: 3444.73 | C10: 344.48 | F10: Transporte
A11: Total general | B11: 275175.6 | C11: 25733.36 | F11: Eventos
F12: Inmobiliario
F13: Náutica
F14: Particulares
F15: Autos
F16: Hogar
F17: Particulares Resto
F18: Personales
F19: Seguros Personales (No Vida) Colectivos
F20: Seguros Personales (No Vida) Particular
B21: añadir credito de Elevia | F21: Vida Ahorro Colectivo
F22: Vida Ahorro Particular
A23: MES ANTERIOR | B23: Prima | C23: Comision | F23: Vida Riesgo Colectivo
A24: Generales | F24: Vida Riesgo Particular
A25: B2B2C | B25: 0 | C25: 0 | F25: Venta cruzada
A26: Arte | B26: 0 | C26: 0 | F26: Total Primas Netas
A27: Caución | B27: 0 | C27: 0
A28: Crédito | B28: 137196.54 | C28: =477.5+16321.05 -> 16798.55
A29: Crédito Internacional | B29: 0 | C29: 0 | F29: Situación | G29: (Todas)
A30: Inmobiliario | B30: 0 | C30: 0 | F30: mes | G30: (Varios elementos)
A31: Eventos | B31: 0 | C31: 0
A32: Property | B32: 0 | C32: 0 | F32: Etiquetas de fila | G32: Suma de Prima neta | H32: Suma de Comisión Bruta
A33: Líneas Financieras | B33: 0 | C33: 0 | F33: Autos
A34: Náutica | B34: 0 | C34: 0 | F34: Caución
A35: Responsabilidad Civil | B35: 0 | C35: 0 | F35: Crédito
A36: Flotas | B36: 0 | C36: 0 | F36: Flotas
A37: Ingeniería | B37: 0 | C37: 0 | F37: Hogar
A38: Transporte | B38: 135226.93 | C38: 13522.72 | F38: Ingenieria
A39: Autos | B39: 826.82 | C39: 57.88 | F39: Ingeniería
A40: Hogar | B40: 0 | C40: 0 | F40: Lineas Financieras
...

Sheet Hoja1

Sheet REPORT
A1: empresa | B1: TIPO_DATO | C1: Fecha facturación | D1: Equivalencia | E1: area | F1: Cliente | G1: Entidad Aseguradora | H1: Venta cruzada | I1: Prima neta | J1: Total Comisión
A2: VEROBROKER | B2: Real | C2: 45931 | D2: Autos | E2: Generales | F2: NETWORK STEEL, S.L. | G2: AXA SEGUROS GENERALES,S.A. DE SEG. Y REASEG. | I2: 697.83 | J2: 38.38
A3: VEROBROKER | B3: Real | C3: 45931 | D3: Autos | E3: Generales | F3: LEON COATED SOLUTIONS, S.L. | G3: MAPFRE ESPAÑA, CIA. DE SEG. Y REASEG.,S.A. | I3: 985.05 | J3: 59.1
A4: VEROBROKER | B4: Real | C4: 45931 | D4: Hogar | E4: Generales | F4: MARIA SACRISTAN MORENO | G4: HELVETIA COMPAÑIA SUIZA,S.A. | I4: 898.91 | J4: 112.36
A5: VEROBROKER | B5: Real | C5: 45938 | D5: Seguros Personales (No Vida) Colectivos | E5: Generales | F5: NETWORK STEEL RESOURCES, S.A | G5: SANITAS, S.A. DE SEGUROS | I5: 66.55 | J5: 3
A6: VEROBROKER | B6: Real | C6: 45938 | D6: Seguros Personales (No Vida) Colectivos | E6: Generales | F6: PLANOS FERRICOS SLU | G6: SANITAS, S.A. DE SEGUROS | I6: 66.55 | J6: 2.66
A7: VEROBROKER | B7: Real | C7: 45938 | D7: Seguros Personales (No Vida) Colectivos | E7: Generales | F7: NETWORK STEEL AFRICA S.L. | G7: SANITAS, S.A. DE SEGUROS | I7: 66.55 | J7: 2.66
A8: VEROBROKER | B8: Real | C8: 45938 | D8: Seguros Personales (No Vida) Colectivos | E8: Generales | F8: NETWORK STEEL, S.L. | G8: SANITAS, S.A. DE SEGUROS | I8: 66.55 | J8: 2.66
A9: VEROBROKER | B9: Real | C9: 45938 | D9: Seguros Personales (No Vida) Colectivos | E9: Generales | F9: NETWORK STEEL RESOURCES, S.A | G9: SANITAS, S.A. DE SEGUROS | I9: 66.55 | J9: 2.66
A10: VEROBROKER | B10: Real | C10: 45938 | D10: Seguros Personales (No Vida) Colectivos | E10: Generales | F10: NETWORK STEEL RESOURCES, S.A | G10: SANITAS, S.A. DE SEGUROS | I10: 318.81 | J10: 13.94
A11: VEROBROKER | B11: Real | C11: 45938 | D11: Seguros Personales (No Vida) Colectivos | E11: Generales | F11: PLANOS FERRICOS SLU | G11: SANITAS, S.A. DE SEGUROS | I11: 66.55 | J11: 3
A12: VEROBROKER | B12: Real | C12: 45938 | D12: Seguros Personales (No Vida) Colectivos | E12: Generales | F12: PLANOS FERRICOS SLU | G12: SANITAS, S.A. DE SEGUROS | I12: 133.1 | J12: 5.32
A13: VEROBROKER | B13: Real | C13: 45938 | D13: Seguros Personales (No Vida) Colectivos | E13: Generales | F13: ECO STEEL SOLUTIONS S.L. | G13: SANITAS, S.A. DE SEGUROS | I13: 133.1 | J13: 5.32
... A127: VEROBROKER | B127: Real | C127: 45931 | D127: Crédito | E127: Generales | F127: PLANOS FERRICOS PORTUGAL PRODUTOS SIDERURGICOS LDA | G127: ATRADIUS CREDITO Y CAUCION S.A. DE SEGUROS Y REASEGUROS | I127: 932.45 | J127: 139.87
A128: VEROBROKER | B128: Real | C128: 45931 | D128: Autos | E128: Generales | I128: -2397 | J128: -131.84
A129: VEROBROKER | B129: Real | C129: 45931 | D129: Crédito | E129: Generales | I129: 2.910383e-11 | J129: 5.2750693e-11
A130: VEROBROKER | B130: Real | C130: 45931 | D130: Flotas | E130: Generales | I130: 2397 | J130: 131.84
A131: VEROBROKER | B131: Real | C131: 45931 | D131: Hogar | E131: Generales | I131: -91925.39 | J131: -6894.4
A132: VEROBROKER | B132: Real | C132: 45931 | D132: Náutica | E132: Generales | I132: 12236 | J132: 1070.65
A133: VEROBROKER | B133: Real | C133: 45931 | D133: Property | E133: Generales | I133: 91925.39 | J133: 6894.4
A134: VEROBROKER | B134: Real | C134: 45931 | D134: Responsabilidad Civil | E134: Generales | I134: -1.4551915e-11 | J134: 0
A135: VEROBROKER | B135: Real | C135: 45931 | D135: Seguros Personales (No Vida) Colectivos | E135: Generales | I135: 9031.92 | J135: 373.73
A136: VEROBROKER | B136: Real | C136: 45931 | D136: Seguros Personales (No Vida) Particular | E136: Generales | I136: -9031.92 | J136: -373.73
A137: VEROBROKER | B137: Real | C137: 45931 | D137: Transporte | E137: Generales | I137: -12236 | J137: -1070.65

Sheet Validación Datos
A1: VALIDACIÓN DATOS
B3: IMPORTES ACUMULADOS
A4: Primas Netas | B4: =+SUM('Modelo Datos'!I:I) -> 287153.66
A5: Comsiones Brutas | B5: =+SUM('Modelo Datos'!J:J) -> 26781.44
A6: Comisión P. Neta | B6: =+SUM('Modelo Datos'!K:K) -> 26781.44
A7: Comsión Colaborador | B7: =+SUM('Modelo Datos'!P:R) -> 0
A9: Verificar que las cifras acumuladas son correctas
