Workbook

Sheet Instrucciones
B5: INSRUCCIONES PARA LA CUMPLIMENTACIÓN DEL FICHERO MENSUAL DE RECIBOS
C7: Fecha límite para la introducción de recibos: El día 6 del mes siguiente
C8: Fecha límite para enviar fichero: Día 7 de cada mes (o el siguiente laborable)
C10: Requisitos información:
C12: - El periodo siempre es el acumulado del año en curso hasta el último día del mes anterior a la fecha de extracción
C13: - Rellenar la pestaña "Modelo Datos", con la siguiente información:
D14: - Recibos facturados en el periodo
D15: - Recibos anulados en el periodo (los importes de primas y comisiones multiplicar x -1)
C16: (Deberían aparecer todos los recibos anulados en el periodo en curso, incluso si estos recibos se facturaron en años anteriores)
C17: - Revisar en la pestaña "Validación de Datos" que las cifras resultantes de Primas y Comiones son correctas
C18: - Rellenar pestaña otros ingresos: Honorarios y/o otras comisiones. (En caso de recibirlos.)
C19: - En caso de no disponer de algún campo, nos lo tendríais que comunicar
C20: - Cambiar el nombre del fichero a: Nombre Correduria_yyyymm
C21: (Eg: Sabseg_202506)
C22: - Enviar vía email el día 7 a:
D23: carles.saez@sabseg.com
D24: pere.torres@sabseg.com
D25: marc.anadon@sabseg.com

Sheet Descripción
A1: MODELO DATOS | B1: DESCRIPCIÓN
A2: Num. Recibo Cía | B2: Número de recibo compañía
A3: Num. Recibo Interno | B3: Número de recibo interno (El que asigna al programa de gestión)
A4: Núm. Póliza Cía | B4: Número de póliza compañía
A5: Núm. Póliza Interno | B5: Número de póliza interno (El que asigna al programa de gestión)
A6: Fecha facturación | B6: Fecha de Facturación o emisión del recibo
A7: Fecha Efecto | B7: Fecha efecto recibo
A8: Producto | B8: Nombre de Producto
A9: Ramo | B9: Nombre de Ramo (con el mayor desglose posible, no ramo DGS)
A10: Prima neta | B10: Prima neta de póliza (sin impuestos)
A11: Comisión Bruta/Correduria | B11: Es la comsión total percibida, incluye sobrecomisión en recibo (si la hay)
A12: Comisión prima neta | B12: Comsión estándar de la póliza, sin la comsión adicional
A13: Comisión complementaria | B13: Comsión adicional, incluida en recibo
A14: Colaborador 1 | B14: Indicar nombre de Colaborador / Auxiliar Externo Si es una venta Cruzada con otra correduria de Sabseg (póliza que le habeis emitido a la otra correduría), indicar como Colaborador a la otra correduría: "VC NOMBRE CORREDURIA" | K14: Póliza que habeis emitido a la otra correduría
A15: Colaborador 2 | B15: Indicar nombre de Colaborador / Auxiliar Externo Si es una venta Cruzada con otra correduria de Sabseg (póliza que le habeis emitido a la otra correduría), indicar como Colaborador a la otra correduría: "VC NOMBRE CORREDURIA" | K15: Póliza que habeis emitido a la otra correduría
A16: Colaborador 3 | B16: Indicar nombre de Colaborador / Auxiliar Externo Si es una venta Cruzada con otra correduria de Sabseg (póliza que le habeis emitido a la otra correduría), indicar como Colaborador a la otra correduría: "VC NOMBRE CORREDURIA" | K16: Póliza que habeis emitido a la otra correduría
A17: Comisión colaborador 1 | B17: Comisión cedida al colaborador o auxiliar externo
A18: Comisión colaborador 2 | B18: Comisión cedida al colaborador o auxiliar externo
A19: Comisión colaborador 3 | B19: Comisión cedida al colaborador o auxiliar externo
A20: Fecha Liquidación Colaborador | B20: Fecha en las que se liquidan las comisiones al colaborador
A21: Tipo Recibo | B21: - Nueva Producción - Cartera - Sup. Cartera … (Las diferentes tipologías de recibo que tengais en vuestro sistema)
A22: Empresa | B22: Nombre de vuestra correduria
A23: Compañía | B23: Aseguradora de la póliza
A24: Gestión | B24: Tipo de gestión/cobro: - Correduría - Compañía (Los diferentes tipos de gestión/cobro del recibo/póliza que tengais en vuestro sistema)
A25: Duracion póliza | B25: Diferenciar por tipo de póliza. Renovable (Genera cartera) y temporales/únicas (No genera cartera).
A26: Situación | B26: - Cobrado - Liquidado - Pendiente - Anulado …. (Las diferentes situaciones del recibo que tengais en vuestro sistema)
A27: Fecha devolución | B27: Fechas de situación de los recibos
A28: Fecha de liquidación
A29: Fecha de cobro
A30: Fecha anulación
A31: Cliente NIF | B31: NIF del cliente
A32: Cliente Nombre | B32: Nombre del cliente o tomador
A33: Tipo Cliente | B33: Particular / Empresa (o Persona Física / Persona Jurídica)
A34: Cliente CP | B34: Código Postal
A36: OTROS INGRESOS | B36: DESCRIPCIÓN
A37: Honorarios | B37: Honorarios percibidos
A38: Cesiones Honorarios | B38: Cesiones a colaboradores de los honorarios percibidos
A39: Otras comisiones | B39: Otras comisiones percibidas por mediación de seguros (colaborador de otra correduria, que no sea SABSEG.)
A40: Cesiones Otras comisiones | B40: Cesiones a colaboradores de otras comisiones

Sheet Modelo Datos
A1: Num. Recibo Cía | B1: Núm. Recibo Interno | C1: Núm. Póliza Cía | D1: Núm. Póliza Interno | E1: Fecha facturación | F1: Fecha Efecto | G1: Producto | H1: Ramo | I1: Prima neta | J1: Comisión Bruta | K1: Comisión prima neta | L1: Comisión complementaria | M1: Colaborador 1 | N1: Colaborador 2 | O1: Colaborador 3 | P1: Comisión colaborador 1 | Q1: Comisión colaborador 2 | R1: Comisión colaborador 3 | S1: Fecha Liquidación Colaborador | T1: Tipo Recibo | U1: Empresa | V1: Compañía | W1: Gestión | X1: Duracion póliza | Y1: Situación | Z1: Fecha devolución | AA1: Fecha de liquidación | AB1: Fecha de cobro | AC1: Fecha anulación | AD1: Cliente NIF | AE1: Cliente Nombre | AF1: Tipo Cliente | AG1: Cliente CP | AH1: mes
D2: L4388595 | E2: 46057 | F2: 46057 | G2: AGROSEGURO | H2: AGROSEGURO | I2: 7730.15 | J2: 773.015 | K2: 618.412 | L2: 154.603 | T2: NP | U2: AGRINALCAZAR | V2: OCCIDENT | Y2: COBRADO | AD2: B30799712 | AE2: EXPLOTACIONES AGRICOLAS JUMAR, S.LL | AF2: EMPRESA | AG2: 30360 | AH2: =+MONTH(E2) -> 2 | AO2: =+MONTH(E2) -> 2
D3: L4391981 | E3: 46059 | F3: 46059 | G3: AGROSEGURO | H3: AGROSEGURO | I3: 2528.9 | J3: 202.312 | K3: 151.734 | L3: 50.578 | T3: NP | U3: AGRINALCAZAR | V3: OCCIDENT | Y3: COBRADO | AD3: B14771331 | AE3: FLORETTE MURCIA, S.L.U. | AF3: EMPRESA | AG3: 31320 | AH3: =+MONTH(E3) -> 2
D4: L4391896 | E4: 46059 | F4: 46059 | G4: AGROSEGURO | H4: AGROSEGURO | I4: 1449.51 | J4: 115.9608 | K4: 86.9706 | L4: 28.9902 | T4: NP | U4: AGRINALCAZAR | V4: OCCIDENT | Y4: COBRADO | AD4: B14771331 | AE4: FLORETTE MURCIA, S.L.U. | AF4: EMPRESA | AG4: 31320 | AH4: =+MONTH(E4) -> 2
D5: L4399095 | E5: 46064 | F5: 46064 | G5: AGROSEGURO | H5: AGROSEGURO | I5: 844.99 | J5: 84.499 | K5: 67.5992 | L5: 16.8998 | T5: NP | U5: AGRINALCAZAR | V5: MAPFRE | Y5: COBRADO | AD5: 29041143D | AE5: BERNARDO CARPENA GARCIA | AF5: PARTICULAR | AG5: 30550 | AH5: =+MONTH(E5) -> 2
D6: L4435731 | E6: 46080 | F6: 46080 | G6: AGROSEGURO | H6: AGROSEGURO | I6: 483.06 | J6: 14.4918 | K6: 4.8306 | L6: 9.6612 | T6: NP | U6: AGRINALCAZAR | V6: ALLIANZ | Y6: COBRADO | AD6: 29040770G | AE6: ORLANDO TURPÍN GÓMEZ | AF6: PARTICULAR | AG6: 30005 | AH6: =+MONTH(E6) -> 2
D7: L4353853 | E7: 46072 | F7: 46072 | G7: AGROSEGURO | H7: AGROSEGURO | I7: 9854.24 | J7: 1182.5088 | K7: 985.424 | L7: 197.0848 | T7: NP | U7: AGRINALCAZAR | V7: OCCIDENT | Y7: COBRADO | AD7: 34800789H | AE7: JORGE VICENTE REVILLA | AF7: PARTICULAR | AG7: 30530 | AH7: =+MONTH(E7) -> 2
D8: L4361704 | E8: 46072 | F8: 46072 | G8: AGROSEGURO | H8: AGROSEGURO | I8: 29601.53 | J8: 3552.1836 | K8: 2960.153 | L8: 592.0306 | T8: NP | U8: AGRINALCAZAR | V8: MAPFRE | Y8: COBRADO | AD8: E75785683 | AE8: HIJOS MATIAS VICENTE, C.B. | AF8: EMPRESA | AG8: 30530 | AH8: =+MONTH(E8) -> 2
D9: L4410505 | E9: 46072 | F9: 46072 | G9: AGROSEGURO | H9: AGROSEGURO | I9: 1352.09 | J9: 135.209 | K9: 108.1672 | L9: 27.0418 | T9: NP | U9: AGRINALCAZAR | V9: ALLIANZ | Y9: COBRADO | AD9: 77568646L | AE9: ANTONIO MORENO CANO | AF9: PARTICULAR | AG9: 30550 | AH9: =+MONTH(E9) -> 2
D10: L4410520 | E10: 46071 | F10: 46071 | G10: AGROSEGURO | H10: AGROSEGURO | I10: 886.94 | J10: 88.694 | K10: 70.9552 | L10: 17.7388 | T10: NP | U10: AGRINALCAZAR | V10: ALLIANZ | Y10: COBRADO | AD10: 48482486G | AE10: PILAR TORNERO MARTINEZ | AF10: PARTICULAR | AG10: 30550 | AH10: =+MONTH(E10) -> 2
D11: L4413121 | E11: 46072 | F11: 46072 | G11: AGROSEGURO | H11: AGROSEGURO | I11: 679.89 | J11: 67.989 | K11: 54.3912 | L11: 13.5978 | T11: NP | U11: AGRINALCAZAR | V11: MAPFRE | Y11: COBRADO | AD11: 77570187L | AE11: JUAN LUCAS RAMOS GARCIA | AF11: PARTICULAR | AG11: 30550 | AH11: =+MONTH(E11) -> 2
D12: L4336316 | E12: 46066 | F12: 46066 | G12: AGROSEGURO | H12: AGROSEGURO | I12: 20382.01 | J12: 2038.201 | K12: 1630.5608 | L12: 407.6402 | T12: NP | U12: AGRINALCAZAR | V12: OCCIDENT | Y12: COBRADO | AD12: B28864817 | AE12: D´QUART | AF12: EMPRESA | AG12: 28003 | AH12: =+MONTH(E12) -> 2
D13: L4336482 | E13: 46066 | F13: 46066 | G13: AGROSEGURO | H13: AGROSEGURO | I13: 10509.03 | J13: 1050.903 | K13: 840.7224 | L13: 210.1806 | T13: NP | U13: AGRINALCAZAR | V13: OCCIDENT | Y13: COBRADO | AD13: B05568944 | AE13: P-CARJAYA, S.L. | AF13: EMPRESA | AG13: 30008 | AH13: =+MONTH(E13) -> 2
D14: L4409610 | E14: 46071 | F14: 46071 | G14: AGROSEGURO | H14: AGROSEGURO | I14: 672.13 | J14: 67.213 | K14: 53.7704 | L14: 13.4426 | T14: NP | U14: AGRINALCAZAR | V14: ALLIANZ | Y14: COBRADO | AD14: 48398357D | AE14: MIGUEL ANGEL LÓPEZ CANDEL | AF14: PARTICULAR | AG14: 30012 | AH14: =+MONTH(E14) -> 2
... D56: L4434913 | E56: 46080 | F56: 46080 | G56: AGROSEGURO | H56: AGROSEGURO | I56: 43933.4 | J56: 4393.34 | K56: 3514.672 | L56: 878.668 | T56: NP | U56: AGRINALCAZAR | V56: OCCIDENT | Y56: COBRADO | AD56: B75604611 | AE56: AGD FINCA LA TORRE, S.L. | AF56: EMPRESA | AG56: 30591 | AH56: =+MONTH(E56) -> 2
D57: M7138863 | E57: 46073 | F57: 46073 | G57: AGROSEGURO | H57: AGROSEGURO | I57: 19187.89 | J57: 2168.2316 | K57: 1976.3527 | L57: 191.8789 | T57: NP | U57: AGRINALCAZAR | V57: MUSSAP | W57: BANASEGUR | Y57: COBRADO | AD57: B05570270 | AE57: EUROSERVICIOS AGRICOLAS MEDITERRANEO SL | AF57: EMPRESA | AG57: 30008 | AH57: =+MONTH(E57) -> 2
D58: M7138874 | E58: 46073 | F58: 46073 | G58: AGROSEGURO | H58: AGROSEGURO | I58: 40792.44 | J58: 4609.5457 | K58: 4201.6213 | L58: 407.9244 | T58: NP | U58: AGRINALCAZAR | V58: MUSSAP | W58: BANASEGUR | Y58: COBRADO | AD58: B05570270 | AE58: EUROSERVICIOS AGRICOLAS MEDITERRANEO SL | AF58: EMPRESA | AG58: 30008 | AH58: =+MONTH(E58) -> 2
D59: M7137776 | E59: 46073 | F59: 46073 | G59: AGROSEGURO | H59: AGROSEGURO | I59: 9362.74 | J59: 1151.617 | K59: 964.36222 | L59: 187.2548 | T59: NP | U59: AGRINALCAZAR | V59: MUSSAP | W59: BANASEGUR | Y59: COBRADO | AD59: B05570288 | AE59: LODAN FRUIT SIGLO XXI, S.L. | AF59: EMPRESA | AG59: 30008 | AH59: =+MONTH(E59) -> 2
D60: M7137780 | E60: 46079 | F60: 46079 | G60: AGROSEGURO | H60: AGROSEGURO | I60: 53751.08 | J60: 6611.3828 | K60: 5536.3612 | L60: 1075.0216 | T60: NP | U60: AGRINALCAZAR | V60: MUSSAP | W60: BANASEGUR | Y60: COBRADO | AD60: B02633626 | AE60: EXPOGROUP REGION DE MURCIA,S .L | AF60: EMPRESA | AG60: 30008 | AH60: =+MONTH(E60) -> 2
D61: L4428543 | E61: 46080 | F61: 46080 | G61: AGROSEGURO | H61: AGROSEGURO | I61: 5589.73 | J61: 558.973 | K61: 447.1784 | L61: 111.7946 | T61: NP | U61: AGRINALCAZAR | V61: OCCIDENT | Y61: COBRADO | AD61: B73357477 | AE61: MARILOZASOL, S.L. | AF61: EMPRESA | AG61: 30360 | AH61: =+MONTH(E61) -> 2
D62: L4428565 | E62: 46080 | F62: 46080 | G62: AGROSEGURO | H62: AGROSEGURO | I62: 4005.55 | J62: 400.555 | K62: 320.444 | L62: 80.111 | T62: NP | U62: AGRINALCAZAR | V62: OCCIDENT | Y62: COBRADO | AD62: B64070642 | AE62: RICOME PRODUCTIONS, S.L. | AF62: EMPRESA | AG62: 30360 | AH62: =+MONTH(E62) -> 2
D63: L4430223 | E63: 46079 | F63: 46079 | G63: AGROSEGURO | H63: AGROSEGURO | I63: 759.66 | J63: 60.7728 | K63: 45.5796 | L63: 15.1932 | T63: NP | U63: AGRINALCAZAR | V63: OCCIDENT | Y63: COBRADO | AD63: B14771331 | AE63: FLORETTE MURCIA S.L.U. | AF63: EMPRESA | AG63: 31320 | AH63: =+MONTH(E63) -> 2
D64: L4430256 | E64: 46079 | F64: 46079 | G64: AGROSEGURO | H64: AGROSEGURO | I64: 6970.17 | J64: 557.6136 | K64: 418.2102 | L64: 139.4034 | T64: NP | U64: AGRINALCAZAR | V64: OCCIDENT | Y64: COBRADO | AD64: B14771331 | AE64: FLORETTE MURCIA S.L.U. | AF64: EMPRESA | AG64: 31320 | AH64: =+MONTH(E64) -> 2
D65: L4430271 | E65: 46079 | F65: 46079 | G65: AGROSEGURO | H65: AGROSEGURO | I65: 1477.47 | J65: 118.1976 | K65: 88.6482 | L65: 29.5494 | T65: NP | U65: AGRINALCAZAR | V65: OCCIDENT | Y65: COBRADO | AD65: B14771331 | AE65: FLORETTE MURCIA S.L.U. | AF65: EMPRESA | AG65: 31320 | AH65: =+MONTH(E65) -> 2
D66: L4426340 | E66: 46078 | F66: 46078 | G66: AGROSEGURO | H66: AGROSEGURO | I66: 2253.38 | J66: 270.4056 | K66: 225.338 | L66: 45.0676 | T66: NP | U66: AGRINALCAZAR | V66: ALLIANZ | Y66: COBRADO | AD66: 52816981B | AE66: ANTONIO JUAN LUCAS GOMEZ | AF66: PARTICULAR | AG66: 30530 | AH66: =+MONTH(E66) -> 2
D67: L4424015 | E67: 46077 | F67: 46077 | G67: AGROSEGURO | H67: AGROSEGURO | I67: 42785.16 | J67: 5989.9224 | K67: 5134.2192 | L67: 855.7032 | T67: NP | U67: AGRINALCAZAR | V67: ALLIANZ | Y67: COBRADO | AD67: B56936479 | AE67: FINCAS BEKHATERA SL | AF67: EMPRESA | AG67: 3460 | AH67: =+MONTH(E67) -> 2
D68: L4424030 | E68: 46077 | F68: 46077 | G68: AGROSEGURO | H68: AGROSEGURO | I68: 26573 | J68: 3720.22 | K68: 3188.76 | L68: 531.46 | T68: NP | U68: AGRINALCAZAR | V68: ALLIANZ | Y68: COBRADO | AD68: B56936479 | AE68: FINCAS BEKHATERA SL | AF68: EMPRESA | AG68: 3460 | AH68: =+MONTH(E68) -> 2
D69: L4432894 | E69: 46080 | F69: 46080 | G69: AGROSEGURO | H69: AGROSEGURO | I69: 10149.57 | J69: 1116.4527 | K69: 913.4613 | L69: 202.9914 | T69: NP | U69: AGRINALCAZAR | V69: ALLIANZ | Y69: COBRADO | AD69: 27450223E | AE69: ISABEL MARTINEZ RUIZ | AF69: PARTICULAR | AG69: 30600 | AH69: =+MONTH(E69) -> 2
D70: L4430293 | E70: 46079 | F70: 46079 | G70: AGROSEGURO | H70: AGROSEGURO | I70: 1405.06 | J70: 196.7084 | K70: 168.6072 | L70: 28.1012 | T70: NP | U70: AGRINALCAZAR | V70: ALLIANZ | Y70: COBRADO | AD70: 34829778G | AE70: JOSE MANUEL GUARDIOLA MARTINEZ | AF70: PARTICULAR | AG70: 30530 | AH70: =+MONTH(E70) -> 2
D71: L4358661 | E71: 46044 | F71: 46044 | G71: AGROSEGURO | H71: AGROSEGURO | I71: 13441.98 | J71: 1344.198 | K71: 1075.3584 | L71: 268.8396 | T71: NP | U71: AGRINALCAZAR | V71: OCCIDENT | Y71: COBRADO | AD71: B30799712 | AE71: EXPLOTACIONES AGRICOLAS JUMAR, S.LL | AF71: EMPRESA | AG71: 30360 | AH71: =+MONTH(E71) -> 1
D72: L4368074 | E72: 46043 | F72: 46043 | G72: AGROSEGURO | H72: AGROSEGURO | I72: 13327.54 | J72: 1332.754 | K72: 1066.2032 | L72: 266.5508 | T72: NP | U72: AGRINALCAZAR | V72: OCCIDENT | Y72: COBRADO | AD72: B30799713 | AE72: EXPLOTACIONES AGRICOLAS JUMAR, S.LL | AF72: EMPRESA | AG72: 30360 | AH72: =+MONTH(E72) -> 1
... D176: L4368553 | E176: 46042 | F176: 46042 | G176: AGROSEGURO | H176: AGROSEGURO | I176: 16008.48 | J176: 1600.848 | K176: 1280.6784 | L176: 320.1696 | T176: NP | U176: AGRINALCAZAR | V176: MAPFRE | Y176: COBRADO | AD176: 29061592B | AE176: FRANCISCO DÍAZ LOZANO | AF176: PARTICULAR | AG176: 30500 | AH176: =+MONTH(E176) -> 1
D177: L4369150 | E177: 46042 | F177: 46042 | G177: AGROSEGURO | H177: AGROSEGURO | I177: 769589.92 | J177: =K177+L177 -> 138526.19 | K177: 115438.49 | L177: 23087.698 | M177: El Ciruelo | P177: 130830.3 | T177: NP | U177: AGRINALCAZAR | V177: MAPFRE | Y177: COBRADO | AD177: B30879480 | AE177: AGRICULTURA DOLORES | AF177: EMPRESA | AG177: 30840 | AH177: =+MONTH(E177) -> 1
D178: L4369194 | E178: 46042 | F178: 46042 | G178: AGROSEGURO | H178: AGROSEGURO | I178: 287104.96 | J178: =K178+L178 -> 66034.141 | K178: 57420.992 | L178: 8613.1488 | M178: El Ciruelo | P178: 63163.091 | T178: NP | U178: AGRINALCAZAR | V178: MAPFRE | Y178: COBRADO | AD178: B73767238 | AE178: AGROFRUITS LEVANTE | AF178: EMPRESA | AG178: 30840 | AH178: =+MONTH(E178) -> 1
D179: L4369242 | E179: 46042 | F179: 46042 | G179: AGROSEGURO | H179: AGROSEGURO | I179: 1494124.3 | J179: =K179+L179 -> 44823.728 | K179: 0 | L179: 44823.728 | M179: El Ciruelo | P179: 29882.488 | T179: NP | U179: AGRINALCAZAR | V179: MAPFRE | Y179: COBRADO | AD179: B73311326 | AE179: AGRICOLA CIRVA | AF179: EMPRESA | AG179: 30840 | AH179: =+MONTH(E179) -> 1
D180: L4369253 | E180: 46042 | F180: 46042 | G180: AGROSEGURO | H180: AGROSEGURO | I180: 19654.61 | J180: 2358.5532 | K180: 1965.461 | L180: 393.0922 | T180: NP | U180: AGRINALCAZAR | V180: ALLIANZ | Y180: COBRADO | AD180: 74286831M | AE180: ALONSO DIAZ PIÑERO | AF180: PARTICULAR | AG180: 30627 | AH180: =+MONTH(E180) -> 1
D181: L4369264 | E181: 46042 | F181: 46042 | G181: AGROSEGURO | H181: AGROSEGURO | I181: 97031.51 | J181: =K181+L181 -> 2910.9453 | K181: 0 | L181: 2910.9453 | M181: El Ciruelo | P181: 1940.6353 | T181: NP | U181: AGRINALCAZAR | V181: MAPFRE | Y181: COBRADO | AD181: B42949636 | AE181: AG GRAPES | AF181: EMPRESA | AG181: 30840 | AH181: =+MONTH(E181) -> 1
D182: L4369356 | E182: 46042 | F182: 46042 | G182: AGROSEGURO | H182: AGROSEGURO | I182: 341197.96 | J182: =K182+L182 -> 75063.551 | K182: 64827.612 | L182: 10235.939 | M182: El Ciruelo | P182: 71651.581 | T182: NP | U182: AGRINALCAZAR | V182: MAPFRE | Y182: COBRADO | AD182: B73767238 | AE182: AGROFUITS LEVANTE | AF182: EMPRESA | AG182: 30840 | AH182: =+MONTH(E182) -> 1
D183: L4369430 | E183: 46042 | F183: 46042 | G183: AGROSEGURO | H183: AGROSEGURO | I183: 31482.23 | J183: =K183+L183 -> 3463.0453 | K183: 2518.5784 | L183: 944.4669 | M183: El Ciruelo | P183: 3148.2253 | T183: NP | U183: AGRINALCAZAR | V183: MAPFRE | Y183: COBRADO | AD183: B73231680 | AE183: AGROCIRUELO | AF183: EMPRESA | AG183: 30840 | AH183: =+MONTH(E183) -> 1
D184: L4370211 | E184: 46044 | F184: 46044 | G184: AGROSEGURO | H184: AGROSEGURO | I184: 5321.27 | J184: 585.3397 | K184: 425.7016 | L184: 159.6381 | T184: NP | U184: AGRINALCAZAR | V184: MAPFRE | Y184: COBRADO | AD184: 22406208E | AE184: ELISA MARTINEZ TORRES | AF184: PARTICULAR | AG184: 30550 | AH184: =+MONTH(E184) -> 1
...

Sheet TD
I3: €' 000 | J3: Prima neta YTD R | K3: Comisiones brutas | L3: SOBRECOMISION | M3: HONORARIOS
A4: Etiquetas de fila | B4: Suma de Prima neta | C4: Suma de Comisión prima neta | D4: Suma de Comisión complementaria | E4: Suma de Comisión colaborador 1 | F4: Honorarios | I4: Agropecuario
A5: 1 | B5: 6008331.2 | C5: 514350.69 | D5: 153142.15 | E5: 300616.32 | F5: 101791.89 | I5: Resto de lineas
A6: 2 | B6: 782833.82 | C6: 65782.463 | D6: 15056.873 | F6: 0
A7: Total general | B7: 6791165 | C7: 580133.16 | D7: 168199.02 | E7: 300616.32 | F7: =+F5+F6 -> 101791.89
I10: mes | J10: 1
I12: Etiquetas de fila | J12: Suma de Prima neta | K12: Suma de Comisión prima neta | L12: Suma de Comisión complementaria | M12: Suma de Comisión colaborador 1 | N12: HONORARIOS
I13: AGROSEGURO | J13: 6008331.2 | K13: 514350.69 | L13: 153142.15 | M13: 300616.32
I14: Total general | J14: 6008331.2 | K14: 514350.69 | L14: 153142.15 | M14: 300616.32 | N14: 101791.89
A15: M-1
A16: Resto de Líneas | B16: 5991693.1 | C16: 512715.7 | D16: 152809.39 | E16: 300616.32 | F16: 101791.89
A18: MES ACTUAL
A19: Resto de lineas | B19: =+B7-B16 -> 799471.96 | C19: =+C7-C16 -> 67417.455 | D19: =+D7-D16 -> 15389.636 | E19: =+E7-E16 -> 0 | F19: =+F7-F16 -> 0 | I19: Ajuste
A20: Elevia | I20: Resto de lineas

Sheet REPORT
A1: empresa | B1: TIPO_DATO | C1: Fecha facturación | D1: Equivalencia | E1: area | F1: Cliente | G1: Entidad Aseguradora | H1: Venta cruzada | I1: Prima neta | J1: Total Comisión
A2: Agrinalcazar | B2: Real | C2: 45961 | D2: Resto de lineas | E2: Agro | F2: FLORETTE MURCIA S.L.U. | G2: OCCIDENT | I2: 487.08 | J2: 19.4832

Sheet Otros ingresos
A1: INDICAR DETALLE DE OTROS INGRESOS DURANTE EL PERIODO
A2: (Honorarios (SIN IVA), comisiones como colaborador de otras corredurias..)
A4: RAMO | B4: Mes | C4: Honorarios | D4: Cesión Honorarios | E4: Otras comisiones | F4: Cesiones Otras Comsiones | G4: Total

Sheet Validación Datos
A1: VALIDACIÓN DATOS
B3: IMPORTES ACUMULADOS
A4: Primas Netas | B4: =+SUM('Modelo Datos'!I:I) -> 6791165
A5: Comsiones Brutas | B5: =+SUM('Modelo Datos'!J:J) -> 748332.18
A6: Comisión P. Neta | B6: =+SUM('Modelo Datos'!K:K) -> 580133.16
A7: Comsión Colaborador | B7: =+SUM('Modelo Datos'!P:R) -> 300616.32
A9: Verificar que las cifras acumuladas son correctas

Sheet clientes
A2: Cliente NIF | B2: nombre | C2: Tipo | D2: cp
A3: 21066346W | B3: =+VLOOKUP(A3,'Modelo Datos'!AD:AF,2,0) -> JOAQUIN GUILLEN GOMEZ | C3: =+VLOOKUP(A3,'Modelo Datos'!AD:AF,3,0) -> PARTICULAR | D3: =+VLOOKUP(A3,'Modelo Datos'!AD:AG,4,0) -> 30609
A4: 22402812F | B4: =+VLOOKUP(A4,'Modelo Datos'!AD:AF,2,0) -> ANTONIO LOPEZ GARCIA | C4: =+VLOOKUP(A4,'Modelo Datos'!AD:AF,3,0) -> PARTICULAR | D4: =+VLOOKUP(A4,'Modelo Datos'!AD:AG,4,0) -> 30550
A5: 22406208E | B5: =+VLOOKUP(A5,'Modelo Datos'!AD:AF,2,0) -> ELISA MARTINEZ TORRES | C5: =+VLOOKUP(A5,'Modelo Datos'!AD:AF,3,0) -> PARTICULAR | D5: =+VLOOKUP(A5,'Modelo Datos'!AD:AG,4,0) -> 30550
A6: 22414243F | B6: =+VLOOKUP(A6,'Modelo Datos'!AD:AF,2,0) -> ISABEL GARCIA GARCIA | C6: =+VLOOKUP(A6,'Modelo Datos'!AD:AF,3,0) -> PARTICULAR | D6: =+VLOOKUP(A6,'Modelo Datos'!AD:AG,4,0) -> 30550
A7: 22424706M | B7: =+VLOOKUP(A7,'Modelo Datos'!AD:AF,2,0) -> ANTONIO TURPIN LUCAS | C7: =+VLOOKUP(A7,'Modelo Datos'!AD:AF,3,0) -> PARTICULAR | D7: =+VLOOKUP(A7,'Modelo Datos'!AD:AG,4,0) -> 30550
A8: 22463786P | B8: =+VLOOKUP(A8,'Modelo Datos'!AD:AF,2,0) -> JUAN GONZALEZ PEREZ | C8: =+VLOOKUP(A8,'Modelo Datos'!AD:AF,3,0) -> PARTICULAR | D8: =+VLOOKUP(A8,'Modelo Datos'!AD:AG,4,0) -> 30559
A9: 22476832J | B9: =+VLOOKUP(A9,'Modelo Datos'!AD:AF,2,0) -> AGUSTINA BASTIDA BALLESTER | C9: =+VLOOKUP(A9,'Modelo Datos'!AD:AF,3,0) -> PARTICULAR | D9: =+VLOOKUP(A9,'Modelo Datos'!AD:AG,4,0) -> 30530
A10: 23024907K | B10: =+VLOOKUP(A10,'Modelo Datos'!AD:AF,2,0) -> JUANA VALERA MENDEZ | C10: =+VLOOKUP(A10,'Modelo Datos'!AD:AF,3,0) -> PARTICULAR | D10: =+VLOOKUP(A10,'Modelo Datos'!AD:AG,4,0) -> 30870
A11: 23040032N | B11: =+VLOOKUP(A11,'Modelo Datos'!AD:AF,2,0) -> BENITO RAJA RAJA | C11: =+VLOOKUP(A11,'Modelo Datos'!AD:AF,3,0) -> PARTICULAR | D11: =+VLOOKUP(A11,'Modelo Datos'!AD:AG,4,0) -> 30870
A12: 23208563E | B12: =+VLOOKUP(A12,'Modelo Datos'!AD:AF,2,0) -> JOSÉ ZAMORA LÓPEZ | C12: =+VLOOKUP(A12,'Modelo Datos'!AD:AF,3,0) -> PARTICULAR | D12: =+VLOOKUP(A12,'Modelo Datos'!AD:AG,4,0) -> 30870
A13: 27435726S | B13: =+VLOOKUP(A13,'Modelo Datos'!AD:AF,2,0) -> JUAN AYALA CANDEL | C13: =+VLOOKUP(A13,'Modelo Datos'!AD:AF,3,0) -> PARTICULAR | D13: =+VLOOKUP(A13,'Modelo Datos'!AD:AG,4,0) -> 30530
A14: 29038614X | B14: =+VLOOKUP(A14,'Modelo Datos'!AD:AF,2,0) -> VILLALBA GUARDIOLA MANUEL | C14: =+VLOOKUP(A14,'Modelo Datos'!AD:AF,3,0) -> PARTICULAR | D14: =+VLOOKUP(A14,'Modelo Datos'!AD:AG,4,0) -> 30530
... A177: B30799713 | B177: =+VLOOKUP(A177,'Modelo Datos'!AD:AF,2,0) -> EXPLOTACIONES AGRICOLAS JUMAR, S.LL | C177: =+VLOOKUP(A177,'Modelo Datos'!AD:AF,3,0) -> EMPRESA | D177: =+VLOOKUP(A177,'Modelo Datos'!AD:AG,4,0) -> 30360
A178: (en blanco)
A179: Total general

Sheet polizas
A2: Núm. Póliza Interno | B2: Suma de Prima neta | C2: Suma de Comisión Bruta | D2: Suma de Comisión prima neta | E2: Suma de Comisión complementaria | F2: NIF | G2: EFECTO | H2: cia | I2: colab1 | J2: com colaborador
A3: L4336316 | B3: 20382.01 | C3: 2038.201 | D3: 1630.5608 | E3: 407.6402 | F3: =+VLOOKUP(A3,'Modelo Datos'!D:AD,27,0) -> B28864817 | G3: =+VLOOKUP(A3,'Modelo Datos'!D:F,3,0) -> 46066 | H3: =+VLOOKUP(A3,'Modelo Datos'!D:AD,19,0) -> OCCIDENT | I3: =+VLOOKUP(A3,'Modelo Datos'!D:AD,10,0) -> 0 | J3: =+VLOOKUP(A3,'Modelo Datos'!D:AD,13,0) -> 0
A4: L4336482 | B4: 10509.03 | C4: 1050.903 | D4: 840.7224 | E4: 210.1806 | F4: =+VLOOKUP(A4,'Modelo Datos'!D:AD,27,0) -> B05568944 | G4: =+VLOOKUP(A4,'Modelo Datos'!D:F,3,0) -> 46066 | H4: =+VLOOKUP(A4,'Modelo Datos'!D:AD,19,0) -> OCCIDENT | I4: =+VLOOKUP(A4,'Modelo Datos'!D:AD,10,0) -> 0 | J4: =+VLOOKUP(A4,'Modelo Datos'!D:AD,13,0) -> 0
A5: L4352861 | B5: 1459.24 | C5: 189.7012 | D5: 145.924 | E5: 43.7772 | F5: =+VLOOKUP(A5,'Modelo Datos'!D:AD,27,0) -> 34807228V | G5: =+VLOOKUP(A5,'Modelo Datos'!D:F,3,0) -> 46037 | H5: =+VLOOKUP(A5,'Modelo Datos'!D:AD,19,0) -> MAPFRE | I5: =+VLOOKUP(A5,'Modelo Datos'!D:AD,10,0) -> 0 | J5: =+VLOOKUP(A5,'Modelo Datos'!D:AD,13,0) -> 0
A6: L4353853 | B6: 9854.24 | C6: 1182.5088 | D6: 985.424 | E6: 197.0848 | F6: =+VLOOKUP(A6,'Modelo Datos'!D:AD,27,0) -> 34800789H | G6: =+VLOOKUP(A6,'Modelo Datos'!D:F,3,0) -> 46072 | H6: =+VLOOKUP(A6,'Modelo Datos'!D:AD,19,0) -> OCCIDENT | I6: =+VLOOKUP(A6,'Modelo Datos'!D:AD,10,0) -> 0 | J6: =+VLOOKUP(A6,'Modelo Datos'!D:AD,13,0) -> 0
A7: L4354520 | B7: 1170.59 | C7: 140.4708 | D7: 117.059 | E7: 23.4118 | F7: =+VLOOKUP(A7,'Modelo Datos'!D:AD,27,0) -> 29039918A | G7: =+VLOOKUP(A7,'Modelo Datos'!D:F,3,0) -> 46073 | H7: =+VLOOKUP(A7,'Modelo Datos'!D:AD,19,0) -> OCCIDENT | I7: =+VLOOKUP(A7,'Modelo Datos'!D:AD,10,0) -> 0 | J7: =+VLOOKUP(A7,'Modelo Datos'!D:AD,13,0) -> 0
A8: L4355706 | B8: 299.18 | C8: 41.8852 | D8: 35.9016 | E8: 5.9836 | F8: =+VLOOKUP(A8,'Modelo Datos'!D:AD,27,0) -> B73956161 | G8: =+VLOOKUP(A8,'Modelo Datos'!D:F,3,0) -> 46024 | H8: =+VLOOKUP(A8,'Modelo Datos'!D:AD,19,0) -> OCCIDENT | I8: =+VLOOKUP(A8,'Modelo Datos'!D:AD,10,0) -> 0 | J8: =+VLOOKUP(A8,'Modelo Datos'!D:AD,13,0) -> 0
A9: L4356911 | B9: 869.3 | C9: 60.851 | D9: 43.465 | E9: 17.386 | F9: =+VLOOKUP(A9,'Modelo Datos'!D:AD,27,0) -> 74336992A | G9: =+VLOOKUP(A9,'Modelo Datos'!D:F,3,0) -> 46029 | H9: =+VLOOKUP(A9,'Modelo Datos'!D:AD,19,0) -> ALLIANZ | I9: =+VLOOKUP(A9,'Modelo Datos'!D:AD,10,0) -> 0 | J9: =+VLOOKUP(A9,'Modelo Datos'!D:AD,13,0) -> 0
A10: L4356992 | B10: 33491.25 | C10: 3684.0375 | D10: 2679.3 | E10: 1004.7375 | F10: =+VLOOKUP(A10,'Modelo Datos'!D:AD,27,0) -> 27435726S | G10: =+VLOOKUP(A10,'Modelo Datos'!D:F,3,0) -> 46029 | H10: =+VLOOKUP(A10,'Modelo Datos'!D:AD,19,0) -> MAPFRE | I10: =+VLOOKUP(A10,'Modelo Datos'!D:AD,10,0) -> 0 | J10: =+VLOOKUP(A10,'Modelo Datos'!D:AD,13,0) -> 0
A11: L4357644 | B11: 20966.33 | C11: 2448.5265 | D11: 2029.1999 | E11: 419.3266 | F11: =+VLOOKUP(A11,'Modelo Datos'!D:AD,27,0) -> 74428802C | G11: =+VLOOKUP(A11,'Modelo Datos'!D:F,3,0) -> 46064 | H11: =+VLOOKUP(A11,'Modelo Datos'!D:AD,19,0) -> ALLIANZ | I11: =+VLOOKUP(A11,'Modelo Datos'!D:AD,10,0) -> 0 | J11: =+VLOOKUP(A11,'Modelo Datos'!D:AD,13,0) -> 0
A12: L4357773 | B12: 2583.3 | C12: 387.495 | D12: 309.996 | E12: 77.499 | F12: =+VLOOKUP(A12,'Modelo Datos'!D:AD,27,0) -> 74346979P | G12: =+VLOOKUP(A12,'Modelo Datos'!D:F,3,0) -> 46030 | H12: =+VLOOKUP(A12,'Modelo Datos'!D:AD,19,0) -> MAPFRE | I12: =+VLOOKUP(A12,'Modelo Datos'!D:AD,10,0) -> 0 | J12: =+VLOOKUP(A12,'Modelo Datos'!D:AD,13,0) -> 0
A13: L4357832 | B13: 2710.03 | C13: 346.88384 | D13: 265.58294 | E13: 81.3009 | F13: =+VLOOKUP(A13,'Modelo Datos'!D:AD,27,0) -> 74317378P | G13: =+VLOOKUP(A13,'Modelo Datos'!D:F,3,0) -> 46030 | H13: =+VLOOKUP(A13,'Modelo Datos'!D:AD,19,0) -> MAPFRE | I13: =+VLOOKUP(A13,'Modelo Datos'!D:AD,10,0) -> 0 | J13: =+VLOOKUP(A13,'Modelo Datos'!D:AD,13,0) -> 0
A14: L4357950 | B14: 9052.78 | C14: 1086.3336 | D14: 814.7502 | E14: 271.5834 | F14: =+VLOOKUP(A14,'Modelo Datos'!D:AD,27,0) -> 29038614X | G14: =+VLOOKUP(A14,'Modelo Datos'!D:F,3,0) -> 46031 | H14: =+VLOOKUP(A14,'Modelo Datos'!D:AD,19,0) -> MAPFRE | I14: =+VLOOKUP(A14,'Modelo Datos'!D:AD,10,0) -> 0 | J14: =+VLOOKUP(A14,'Modelo Datos'!D:AD,13,0) -> 0
... A207: M7138874 | B207: 40792.44 | C207: 4609.5457 | D207: 4201.6213 | E207: 407.9244 | F207: =+VLOOKUP(A207,'Modelo Datos'!D:AD,27,0) -> B05570270 | G207: =+VLOOKUP(A207,'Modelo Datos'!D:F,3,0) -> 46073 | H207: =+VLOOKUP(A207,'Modelo Datos'!D:AD,19,0) -> MUSSAP | I207: =+VLOOKUP(A207,'Modelo Datos'!D:AD,10,0) -> 0 | J207: =+VLOOKUP(A207,'Modelo Datos'!D:AD,13,0) -> 0
A208: (en blanco) | F208: =+VLOOKUP(A208,'Modelo Datos'!D:AD,27,0) -> #N/A | H208: =+VLOOKUP(A208,'Modelo Datos'!D:AD,19,0) -> #N/A | I208: =+VLOOKUP(A208,'Modelo Datos'!D:AD,10,0) -> #N/A | J208: =+VLOOKUP(A208,'Modelo Datos'!D:AD,13,0) -> #N/A
A209: Total general | B209: 6791165 | C209: 748332.18 | D209: 580133.16 | E209: 168199.02 | F209: =+VLOOKUP(A209,'Modelo Datos'!D:AD,27,0) -> #N/A | H209: =+VLOOKUP(A209,'Modelo Datos'!D:AD,19,0) -> #N/A | I209: =+VLOOKUP(A209,'Modelo Datos'!D:AD,10,0) -> #N/A | J209: =+VLOOKUP(A209,'Modelo Datos'!D:AD,13,0) -> #N/A
