Workbook

Sheet TD
A2: Grupo Ramo2 | B2: Suma de Prima neta | C2: Suma de Comisión prima neta | D2: Suma de Comisión complementaria | E2: Suma de Comisión colaborador
A3: Autos | B3: 91830.96 | C3: 11457.53 | D3: 230.12 | E3: 33.54
A4: Flotas | B4: 2343138.7 | C4: 269823.97 | D4: 637 | E4: 2353.22
A5: Hogar | B5: 11331.92 | C5: 2812.44 | D5: 0 | E5: 0
A6: Ingeniería | B6: 10471.9 | C6: 1737.73 | D6: 339.74 | E6: 0
A7: Líneas Financieras | B7: 13408.47 | C7: 2725.6 | D7: 0 | E7: 0
A8: Náutica | B8: 44.88 | C8: 7.85 | D8: 0 | E8: 0
A9: Particulares Resto | B9: 4341.64 | C9: 1098.64 | D9: 0 | E9: 9.44
A10: Property | B10: 55367.36 | C10: 11810.86 | D10: 78.84 | E10: 56.91
A11: Responsabilidad Civil | B11: 68815.44 | C11: 13779.49 | D11: 198.16 | E11: 59.83
A12: Resto de lineas | B12: 19024.27 | C12: 1464.06 | D12: 0 | E12: 0
A13: Seguros Personales (No Vida) Colectivos | B13: 32195.11 | C13: 6329.09 | D13: 66.66 | E13: 48.69
A14: Seguros Personales (No Vida) Particular | B14: 79384.48 | C14: 7066.48 | D14: 12.91 | E14: 0
... A19: Total general | B19: 3220079.9 | C19: 432985.37 | D19: 2010.37 | E19: 2942.22
I22: mes | J22: 2
A23: M-1
A24: Grupo Ramo2 | B24: Suma de Prima neta | C24: Suma de Comisión prima neta | D24: Suma de Comisión complementaria | E24: Suma de Comisión colaborador | I24: Grupo Ramo2 | J24: Suma de Prima neta | K24: Suma de Comisión prima neta | L24: Suma de Comisión complementaria | M24: Suma de Comisión colaborador
A25: Autos | B25: 65616.9 | C25: 8185.05 | D25: 157.24 | E25: 5.5 | I25: Autos | J25: 25760.95 | K25: 3199.98 | L25: 30.52 | M25: 28.04
A26: Flotas | B26: 1970814.9 | C26: 226315.43 | D26: 466.8 | E26: 1067.87 | I26: Flotas | J26: 239219.58 | K26: 27513.28 | L26: 173.58 | M26: 740.76
A27: Hogar | B27: 12062.32 | C27: 3087.19 | D27: 0 | E27: 0 | I27: Hogar | J27: 1838.52 | K27: 367.53 | L27: 0 | M27: 0
A28: Ingeniería | B28: 3466.87 | C28: 662.94 | D28: 0 | E28: 0 | I28: Ingeniería | J28: 4828.03 | K28: 724.2 | L28: 254.68 | M28: 0
A29: Líneas Financieras | B29: 6863.92 | C29: 1330.67 | D29: 0 | E29: 0 | I29: Líneas Financieras | J29: 6544.55 | K29: 1394.93 | L29: 0 | M29: 0
A30: Particulares Resto | B30: 3006.94 | C30: 819.05 | D30: 0 | E30: 9.44 | I30: Náutica | J30: 44.88 | K30: 7.85 | L30: 0 | M30: 0
A31: Property | B31: 49479.94 | C31: 10486.8 | D31: 16.8 | E31: 56.91 | I31: Particulares Resto | J31: 1334.7 | K31: 263.63 | L31: 0 | M31: 0
A32: Responsabilidad Civil | B32: 53225.41 | C32: 10652.89 | D32: 0 | E32: 31.65 | I32: Property | J32: 6417.93 | K32: 1437.07 | L32: 14.64 | M32: 0
A33: Seguros Personales (No Vida) Colectivos | B33: 20726.07 | C33: 4181.97 | D33: 24.77 | E33: 31.88 | I33: Responsabilidad Civil | J33: 15590.03 | K33: 3126.6 | L33: 198.16 | M33: 28.18
A34: Seguros Personales (No Vida) Particular | B34: 45806.53 | C34: 4037.57 | D34: 12.91 | E34: 0 | I34: Resto de lineas | J34: 19024.27 | K34: 1464.06 | L34: 0 | M34: 0
A35: Transporte | B35: 471606.08 | C35: 99602.27 | D35: 292.86 | E35: 363.01 | I35: Seguros Personales (No Vida) Colectivos | J35: 11020.45 | K35: 2057.41 | L35: 29.92 | M35: 5.74
A36: Vida Ahorro Particular | B36: -92.92 | C36: 24.31 | D36: 0 | E36: 0 | I36: Seguros Personales (No Vida) Particular | J36: 33151.47 | K36: 2980.71 | L36: 0 | M36: 0
... A39: Total general | B39: 2707449.3 | C39: 370330.88 | D39: 1121.47 | E39: 1566.26 | I39: Vida Riesgo Particular | J39: 1375.58 | K39: 298.35 | L39: 0 | M39: 0
I40: Total general | J40: 376424.24 | K40: 46354.08 | L40: 705.49 | M40: 820.3
A49: Agro
A50: Resto de Lineas | B50: =IFERROR(VLOOKUP(A50,$A$3:$B$21,2,0),0)-IFERROR(VLOOKUP(A50,$A$24:$C$42,2,0),0) -> 19024.27 | C50: =IFERROR(VLOOKUP(A50,$A$3:$C$22,3,0),0)-IFERROR(VLOOKUP(A50,$A$24:$C$42,3,0),0) -> 1464.06
A51: Retirada | B51: =IFERROR(VLOOKUP(A51,$A$3:$B$21,2,0),0)-IFERROR(VLOOKUP(A51,$A$24:$C$42,2,0),0) -> 0 | C51: =IFERROR(VLOOKUP(A51,$A$3:$C$22,3,0),0)-IFERROR(VLOOKUP(A51,$A$24:$C$42,3,0),0) -> 0
A52: Vida Ganado | B52: =IFERROR(VLOOKUP(A52,$A$3:$B$21,2,0),0)-IFERROR(VLOOKUP(A52,$A$24:$C$42,2,0),0) -> 0 | C52: =IFERROR(VLOOKUP(A52,$A$3:$C$22,3,0),0)-IFERROR(VLOOKUP(A52,$A$24:$C$42,3,0),0) -> 0
A53: Generales | B53: =IFERROR(VLOOKUP(A53,$A$3:$B$21,2,0),0)-IFERROR(VLOOKUP(A53,$A$24:$C$42,2,0),0) -> 0 | C53: =IFERROR(VLOOKUP(A53,$A$3:$C$22,3,0),0)-IFERROR(VLOOKUP(A53,$A$24:$C$42,3,0),0) -> 0
A54: B2B2C | B54: =IFERROR(VLOOKUP(A54,$A$3:$B$21,2,0),0)-IFERROR(VLOOKUP(A54,$A$24:$C$42,2,0),0) -> 0 | C54: =IFERROR(VLOOKUP(A54,$A$3:$C$22,3,0),0)-IFERROR(VLOOKUP(A54,$A$24:$C$42,3,0),0) -> 0
A55: Arte | B55: =IFERROR(VLOOKUP(A55,$A$3:$B$21,2,0),0)-IFERROR(VLOOKUP(A55,$A$24:$C$42,2,0),0) -> 0 | C55: =IFERROR(VLOOKUP(A55,$A$3:$C$22,3,0),0)-IFERROR(VLOOKUP(A55,$A$24:$C$42,3,0),0) -> 0
A56: Caución | B56: =IFERROR(VLOOKUP(A56,$A$3:$B$21,2,0),0)-IFERROR(VLOOKUP(A56,$A$24:$C$42,2,0),0) -> 0 | C56: =IFERROR(VLOOKUP(A56,$A$3:$C$22,3,0),0)-IFERROR(VLOOKUP(A56,$A$24:$C$42,3,0),0) -> 0
A57: Crédito Nacional | B57: =IFERROR(VLOOKUP(A57,$A$3:$B$21,2,0),0)-IFERROR(VLOOKUP(A57,$A$24:$C$42,2,0),0) -> 0 | C57: =IFERROR(VLOOKUP(A57,$A$3:$C$22,3,0),0)-IFERROR(VLOOKUP(A57,$A$24:$C$42,3,0),0) -> 0
...

Sheet Sheet1
A1: Num. recibo | B1: Código recibo compañia | C1: Núm. Póliza | D1: Fecha anulación | E1: Fecha facturación | F1: Fecha Efecto | G1: Cliente | H1: Producto | I1: Ramo | J1: Prima neta | K1: . | L1: Comisión correduría | M1: .. | N1: Comisión prima neta | O1: ... | P1: Comisión complementaria | Q1: .... | R1: 1º Colaborador | S1: Comisión colaborador | T1: ..... | U1: Tipo | V1: Situación | W1: Empresa | X1: Compañía | Y1: Grupo Ramo | Z1: Gestión | AA1: Cliente.Direccion.CP | AB1: Cliente.Direccion.Localidad | AC1: Poliza.Cliente.Entidad | AD1: NIF | AE1: Ramo 2 | AF1: Grupo Ramo | AG1: Compañía | AH1: mes
A2: 2026000002 | B2: 469628063-J | C2: GPDIA3000224 | D2: 46023 | E2: 46023 | F2: 46023 | G2: RENOVATIA ACTIVOS, S.L.U. | H2: HOGAR PLUS 2015 | I2: M.HOGAR | J2: 150.61 | K2: Eur. | L2: 37.65 | M2: Eur. | N2: 37.65 | O2: Eur. | P2: 0 | Q2: Eur. | S2: 0,00 | T2: Eur. | U2: Cartera | V2: Anulado_Cia | W2: BANASEG-SV | X2: OCCIDENT GCO, S.A.U. DE SEGUROS Y REASEGUROS | Y2: M.HOGAR | Z2: Correduría | AA2: 47012 | AB2: VALLADOLID VALLADOLID | AC2: Empresa | AD2: B-47567334 | AE2: =+VLOOKUP(H2,'Mapeo Ramos'!A:C,3,0) -> Hogar | AF2: =+VLOOKUP(AE2,'Mapeo Ramos'!C:D,2,0) -> Hogar | AG2: =+VLOOKUP(X2,'Mapeo Ramos'!I:J,2,0) -> OCCIDENT | AH2: =+MONTH(E2) -> 1
A3: 2026000004 | B3: 469653253-C | C3: 547654663 | D3: 46023 | E3: 46023 | F3: 46023 | G3: RENOVATIA ACTIVOS, S.L.U. | H3: HOGAR PLUS 2015 | I3: M.HOGAR | J3: 160.31 | K3: Eur. | L3: 40.08 | M3: Eur. | N3: 40.08 | O3: Eur. | P3: 0 | Q3: Eur. | S3: 0,00 | T3: Eur. | U3: Cartera | V3: Anulado_Cia | W3: BANASEG-SV | X3: OCCIDENT GCO, S.A.U. DE SEGUROS Y REASEGUROS | Y3: M.HOGAR | Z3: Correduría | AA3: 47012 | AB3: VALLADOLID VALLADOLID | AC3: Empresa | AD3: B-47567334 | AE3: =+VLOOKUP(H3,'Mapeo Ramos'!A:C,3,0) -> Hogar | AF3: =+VLOOKUP(AE3,'Mapeo Ramos'!C:D,2,0) -> Hogar | AG3: =+VLOOKUP(X3,'Mapeo Ramos'!I:J,2,0) -> OCCIDENT | AH3: =+MONTH(E3) -> 1
A4: 2026000007 | B4: 469653252-T | C4: 547654662 | D4: 46023 | E4: 46023 | F4: 46023 | G4: RENOVATIA ACTIVOS, S.L.U. | H4: HOGAR PLUS 2015 | I4: M.HOGAR | J4: 147.42 | K4: Eur. | L4: 36.85 | M4: Eur. | N4: 36.85 | O4: Eur. | P4: 0 | Q4: Eur. | S4: 0,00 | T4: Eur. | U4: Cartera | V4: Anulado_Cia | W4: BANASEG-SV | X4: OCCIDENT GCO, S.A.U. DE SEGUROS Y REASEGUROS | Y4: M.HOGAR | Z4: Correduría | AA4: 47012 | AB4: VALLADOLID VALLADOLID | AC4: Empresa | AD4: B-47567334 | AE4: =+VLOOKUP(H4,'Mapeo Ramos'!A:C,3,0) -> Hogar | AF4: =+VLOOKUP(AE4,'Mapeo Ramos'!C:D,2,0) -> Hogar | AG4: =+VLOOKUP(X4,'Mapeo Ramos'!I:J,2,0) -> OCCIDENT | AH4: =+MONTH(E4) -> 1
A5: 2026000006 | B5: 469653254-L | C5: 547654667 | D5: 46023 | E5: 46023 | F5: 46023 | G5: RENOVATIA ACTIVOS, S.L.U. | H5: HOGAR PLUS 2015 | I5: M.HOGAR | J5: 145.23 | K5: Eur. | L5: 36.31 | M5: Eur. | N5: 36.31 | O5: Eur. | P5: 0 | Q5: Eur. | S5: 0,00 | T5: Eur. | U5: Cartera | V5: Anulado_Cia | W5: BANASEG-SV | X5: OCCIDENT GCO, S.A.U. DE SEGUROS Y REASEGUROS | Y5: M.HOGAR | Z5: Correduría | AA5: 47012 | AB5: VALLADOLID VALLADOLID | AC5: Empresa | AD5: B-47567334 | AE5: =+VLOOKUP(H5,'Mapeo Ramos'!A:C,3,0) -> Hogar | AF5: =+VLOOKUP(AE5,'Mapeo Ramos'!C:D,2,0) -> Hogar | AG5: =+VLOOKUP(X5,'Mapeo Ramos'!I:J,2,0) -> OCCIDENT | AH5: =+MONTH(E5) -> 1
A6: 2026000011 | B6: 469691708-T | C6: 548382890 | D6: 46023 | E6: 46023 | F6: 46023 | G6: RENOVATIA ACTIVOS, S.L.U. | H6: HOGAR PLUS 2015 | I6: M.HOGAR | J6: 1337.64 | K6: Eur. | L6: 334.41 | M6: Eur. | N6: 334.41 | O6: Eur. | P6: 0 | Q6: Eur. | S6: 0,00 | T6: Eur. | U6: Cartera | V6: Anulado_Cia | W6: BANASEG-SV | X6: OCCIDENT GCO, S.A.U. DE SEGUROS Y REASEGUROS | Y6: M.HOGAR | Z6: Correduría | AA6: 47012 | AB6: VALLADOLID VALLADOLID | AC6: Empresa | AD6: B-47567334 | AE6: =+VLOOKUP(H6,'Mapeo Ramos'!A:C,3,0) -> Hogar | AF6: =+VLOOKUP(AE6,'Mapeo Ramos'!C:D,2,0) -> Hogar | AG6: =+VLOOKUP(X6,'Mapeo Ramos'!I:J,2,0) -> OCCIDENT | AH6: =+MONTH(E6) -> 1
A7: 2026000010 | B7: 469667701-M | C7: 547986242 | D7: 46023 | E7: 46023 | F7: 46023 | G7: INDAMAL, S.L. | H7: HOGAR PLUS 2015 | I7: M.HOGAR | J7: 235.35 | K7: Eur. | L7: 58.84 | M7: Eur. | N7: 58.84 | O7: Eur. | P7: 0 | Q7: Eur. | S7: 0,00 | T7: Eur. | U7: Cartera | V7: Anulado_Cia | W7: BANASEG-SV | X7: OCCIDENT GCO, S.A.U. DE SEGUROS Y REASEGUROS | Y7: M.HOGAR | Z7: Correduría | AA7: 47012 | AB7: VALLADOLID VALLADOLID | AC7: Empresa | AD7: B-47486089 | AE7: =+VLOOKUP(H7,'Mapeo Ramos'!A:C,3,0) -> Hogar | AF7: =+VLOOKUP(AE7,'Mapeo Ramos'!C:D,2,0) -> Hogar | AG7: =+VLOOKUP(X7,'Mapeo Ramos'!I:J,2,0) -> OCCIDENT | AH7: =+MONTH(E7) -> 1
A8: 2026000013 | B8: 469705493-N | C8: 548645048 | D8: 46023 | E8: 46023 | F8: 46023 | G8: RENOVATIA ACTIVOS, S.L.U. | H8: HOGAR PLUS 2015 | I8: M.HOGAR | J8: 196.18 | K8: Eur. | L8: 49.04 | M8: Eur. | N8: 49.04 | O8: Eur. | P8: 0 | Q8: Eur. | S8: 0,00 | T8: Eur. | U8: Cartera | V8: Anulado_Cia | W8: BANASEG-SV | X8: OCCIDENT GCO, S.A.U. DE SEGUROS Y REASEGUROS | Y8: M.HOGAR | Z8: Correduría | AA8: 47012 | AB8: VALLADOLID VALLADOLID | AC8: Empresa | AD8: B-47567334 | AE8: =+VLOOKUP(H8,'Mapeo Ramos'!A:C,3,0) -> Hogar | AF8: =+VLOOKUP(AE8,'Mapeo Ramos'!C:D,2,0) -> Hogar | AG8: =+VLOOKUP(X8,'Mapeo Ramos'!I:J,2,0) -> OCCIDENT | AH8: =+MONTH(E8) -> 1
A9: 2026000014 | B9: 469705350-V | C9: 548644573 | D9: 46023 | E9: 46023 | F9: 46023 | G9: RENOVATIA ACTIVOS, S.L.U. | H9: HOGAR PLUS 2015 | I9: M.HOGAR | J9: 196.18 | K9: Eur. | L9: 49.04 | M9: Eur. | N9: 49.04 | O9: Eur. | P9: 0 | Q9: Eur. | S9: 0,00 | T9: Eur. | U9: Cartera | V9: Anulado_Cia | W9: BANASEG-SV | X9: OCCIDENT GCO, S.A.U. DE SEGUROS Y REASEGUROS | Y9: M.HOGAR | Z9: Correduría | AA9: 47012 | AB9: VALLADOLID VALLADOLID | AC9: Empresa | AD9: B-47567334 | AE9: =+VLOOKUP(H9,'Mapeo Ramos'!A:C,3,0) -> Hogar | AF9: =+VLOOKUP(AE9,'Mapeo Ramos'!C:D,2,0) -> Hogar | AG9: =+VLOOKUP(X9,'Mapeo Ramos'!I:J,2,0) -> OCCIDENT | AH9: =+MONTH(E9) -> 1
A10: 2026000017 | B10: 470042572-K | C10: GPDIN2700070 | D10: 46023 | E10: 46023 | F10: 46023 | G10: RENOVATIA ACTIVOS, S.L.U. | H10: COMERCIO PLUS | I10: M.COMERCIO | J10: 318.5 | K10: Eur. | L10: 71.66 | M10: Eur. | N10: 71.66 | O10: Eur. | P10: 0 | Q10: Eur. | S10: 0,00 | T10: Eur. | U10: Cartera | V10: Anulado_Cia | W10: BANASEG-SV | X10: OCCIDENT GCO, S.A.U. DE SEGUROS Y REASEGUROS | Y10: M.COMERCIO | Z10: Correduría | AA10: 47012 | AB10: VALLADOLID VALLADOLID | AC10: Empresa | AD10: B-47567334 | AE10: =+VLOOKUP(H10,'Mapeo Ramos'!A:C,3,0) -> Multirriesgo Comercios | AF10: =+VLOOKUP(AE10,'Mapeo Ramos'!C:D,2,0) -> Property | AG10: =+VLOOKUP(X10,'Mapeo Ramos'!I:J,2,0) -> OCCIDENT | AH10: =+MONTH(E10) -> 1
A11: 2026000033 | B11: 470787435-E | C11: 548626952 | D11: 46023 | E11: 46023 | F11: 46025 | G11: CARRETILLAS MAYOR, S.A. | H11: TURISMOS | I11: AUTOS | J11: 544.72 | K11: Eur. | L11: 65.36 | M11: Eur. | N11: 65.36 | O11: Eur. | P11: 0 | Q11: Eur. | S11: 0,00 | T11: Eur. | U11: Cartera | V11: Anulado_Cia | W11: BANASEG-SV | X11: OCCIDENT GCO, S.A.U. DE SEGUROS Y REASEGUROS | Y11: AUTOS | Z11: Correduría | AA11: 47260 | AB11: CABEZON DE PISUERGA VALLADOLID | AC11: Empresa | AD11: A-47067509 | AE11: =+VLOOKUP(H11,'Mapeo Ramos'!A:C,3,0) -> Autos Cat. 1 | AF11: =+VLOOKUP(AE11,'Mapeo Ramos'!C:D,2,0) -> Autos | AG11: =+VLOOKUP(X11,'Mapeo Ramos'!I:J,2,0) -> OCCIDENT | AH11: =+MONTH(E11) -> 1
A12: 2026000034 | B12: 470787456-M | C12: 548626974 | D12: 46023 | E12: 46023 | F12: 46025 | G12: CARRETILLAS MAYOR, S.A. | H12: TURISMOS | I12: AUTOS | J12: 577.24 | K12: Eur. | L12: 69.26 | M12: Eur. | N12: 69.26 | O12: Eur. | P12: 0 | Q12: Eur. | S12: 0,00 | T12: Eur. | U12: Cartera | V12: Anulado_Cia | W12: BANASEG-SV | X12: OCCIDENT GCO, S.A.U. DE SEGUROS Y REASEGUROS | Y12: AUTOS | Z12: Correduría | AA12: 47260 | AB12: CABEZON DE PISUERGA VALLADOLID | AC12: Empresa | AD12: A-47067509 | AE12: =+VLOOKUP(H12,'Mapeo Ramos'!A:C,3,0) -> Autos Cat. 1 | AF12: =+VLOOKUP(AE12,'Mapeo Ramos'!C:D,2,0) -> Autos | AG12: =+VLOOKUP(X12,'Mapeo Ramos'!I:J,2,0) -> OCCIDENT | AH12: =+MONTH(E12) -> 1
A13: 2026000035 | B13: 470787464-G | C13: 548626983 | D13: 46023 | E13: 46023 | F13: 46025 | G13: CARRETILLAS MAYOR, S.A. | H13: TURISMOS | I13: AUTOS | J13: 597.46 | K13: Eur. | L13: 71.7 | M13: Eur. | N13: 71.7 | O13: Eur. | P13: 0 | Q13: Eur. | S13: 0,00 | T13: Eur. | U13: Cartera | V13: Anulado_Cia | W13: BANASEG-SV | X13: OCCIDENT GCO, S.A.U. DE SEGUROS Y REASEGUROS | Y13: AUTOS | Z13: Correduría | AA13: 47260 | AB13: CABEZON DE PISUERGA VALLADOLID | AC13: Empresa | AD13: A-47067509 | AE13: =+VLOOKUP(H13,'Mapeo Ramos'!A:C,3,0) -> Autos Cat. 1 | AF13: =+VLOOKUP(AE13,'Mapeo Ramos'!C:D,2,0) -> Autos | AG13: =+VLOOKUP(X13,'Mapeo Ramos'!I:J,2,0) -> OCCIDENT | AH13: =+MONTH(E13) -> 1
... A37: 2026000344 | B37: 7601075821 | C37: D9A620000033 | D37: 46023 | E37: 46023 | F37: 46023 | G37: LOGISTICA Y DISTRIBUCION BARROSO, S.L. | H37: HELVETIA SEMI REMOLQUES | I37: AUTOS | J37: 463.07 | K37: Eur. | L37: 64.84 | M37: Eur. | N37: 64.84 | O37: Eur. | P37: 0 | Q37: Eur. | S37: 0,00 | T37: Eur. | U37: Cartera | V37: Anulado_Cia | W37: BANASEG-SV | X37: HELVETIA | Y37: AUTOS | Z37: Correduría | AA37: 41770 | AB37: MONTELLANO SEVILLA | AC37: Empresa | AD37: B-90000282 | AE37: =+VLOOKUP(H37,'Mapeo Ramos'!A:C,3,0) -> Autos Cat. 2 | AF37: =+VLOOKUP(AE37,'Mapeo Ramos'!C:D,2,0) -> Flotas | AG37: =+VLOOKUP(X37,'Mapeo Ramos'!I:J,2,0) -> HELVETIA | AH37: =+MONTH(E37) -> 1
A38: 2026000346 | B38: 7601075822 | C38: D9A960000003 | D38: 46023 | E38: 46023 | F38: 46023 | G38: ANDRES SDAD COOP. | H38: HELVETIA FLOTAS | I38: AUTO FLOTA | J38: 139.21 | K38: Eur. | L38: 19.46 | M38: Eur. | N38: 19.46 | O38: Eur. | P38: 0 | Q38: Eur. | R38: ASETRA | S38: 3.48 | T38: Eur. | U38: Cartera | V38: Anulado_Cia | W38: BANASEG-SV | X38: HELVETIA | Y38: AUTOS | Z38: Correduría | AA38: 47350 | AB38: QUINTANILLA DE ONESIMO VALLADOLID | AC38: Empresa | AD38: F-47303029 | AE38: =+VLOOKUP(H38,'Mapeo Ramos'!A:C,3,0) -> Autos Flotas | AF38: =+VLOOKUP(AE38,'Mapeo Ramos'!C:D,2,0) -> Flotas | AG38: =+VLOOKUP(X38,'Mapeo Ramos'!I:J,2,0) -> HELVETIA | AH38: =+MONTH(E38) -> 1
A39: 2026000348 | B39: 7601075825 | C39: V4A960000011 | D39: 46023 | E39: 46023 | F39: 46023 | G39: HERMANOS ANDRES CALLEJA, S.L. | H39: HELVETIA FLOTAS | I39: AUTO FLOTA | J39: 5593.53 | K39: Eur. | L39: 783.08 | M39: Eur. | N39: 783.08 | O39: Eur. | P39: 0 | Q39: Eur. | R39: ASETRA | S39: 139.84 | T39: Eur. | U39: Cartera | V39: Anulado_Cia | W39: BANASEG-SV | X39: HELVETIA | Y39: AUTOS | Z39: Correduría | AA39: 47350 | AB39: QUINTANILLA DE ONESIMO VALLADOLID | AC39: Empresa | AD39: B-47358288 | AE39: =+VLOOKUP(H39,'Mapeo Ramos'!A:C,3,0) -> Autos Flotas | AF39: =+VLOOKUP(AE39,'Mapeo Ramos'!C:D,2,0) -> Flotas | AG39: =+VLOOKUP(X39,'Mapeo Ramos'!I:J,2,0) -> HELVETIA | AH39: =+MONTH(E39) -> 1
A40: 2026000359 | B40: 7601075836 | C40: D9H150004281 | D40: 46023 | E40: 46023 | F40: 46023 | G40: INDAMAL, S.L. | H40: HOGAR ELITE/VITAL/TOP | I40: M.HOGAR | J40: 289.16 | K40: Eur. | L40: 72.31 | M40: Eur. | N40: 72.31 | O40: Eur. | P40: 0 | Q40: Eur. | S40: 0,00 | T40: Eur. | U40: Cartera | V40: Anulado_Cia | W40: BANASEG-SV | X40: HELVETIA | Y40: M.HOGAR | Z40: Correduría | AA40: 47012 | AB40: VALLADOLID VALLADOLID | AC40: Empresa | AD40: B-47486089 | AE40: =+VLOOKUP(H40,'Mapeo Ramos'!A:C,3,0) -> Hogar | AF40: =+VLOOKUP(AE40,'Mapeo Ramos'!C:D,2,0) -> Hogar | AG40: =+VLOOKUP(X40,'Mapeo Ramos'!I:J,2,0) -> HELVETIA | AH40: =+MONTH(E40) -> 1
A41: 2026000360 | B41: 7601075838 | C41: D9H150005170 | D41: 46023 | E41: 46023 | F41: 46023 | G41: INDAMAL, S.L. | H41: HOGAR ELITE/VITAL/TOP | I41: M.HOGAR | J41: 153.64 | K41: Eur. | L41: 38.42 | M41: Eur. | N41: 38.42 | O41: Eur. | P41: 0 | Q41: Eur. | S41: 0,00 | T41: Eur. | U41: Cartera | V41: Anulado_Cia | W41: BANASEG-SV | X41: HELVETIA | Y41: M.HOGAR | Z41: Correduría | AA41: 47012 | AB41: VALLADOLID VALLADOLID | AC41: Empresa | AD41: B-47486089 | AE41: =+VLOOKUP(H41,'Mapeo Ramos'!A:C,3,0) -> Hogar | AF41: =+VLOOKUP(AE41,'Mapeo Ramos'!C:D,2,0) -> Hogar | AG41: =+VLOOKUP(X41,'Mapeo Ramos'!I:J,2,0) -> HELVETIA | AH41: =+MONTH(E41) -> 1
A42: 2026000362 | B42: 7601075837 | C42: D9H150004555 | D42: 46023 | E42: 46023 | F42: 46023 | G42: INDAMAL, S.L. | H42: HOGAR ELITE/VITAL/TOP | I42: M.HOGAR | J42: 206.98 | K42: Eur. | L42: 51.76 | M42: Eur. | N42: 51.76 | O42: Eur. | P42: 0 | Q42: Eur. | S42: 0,00 | T42: Eur. | U42: Cartera | V42: Anulado_Cia | W42: BANASEG-SV | X42: HELVETIA | Y42: M.HOGAR | Z42: Correduría | AA42: 47012 | AB42: VALLADOLID VALLADOLID | AC42: Empresa | AD42: B-47486089 | AE42: =+VLOOKUP(H42,'Mapeo Ramos'!A:C,3,0) -> Hogar | AF42: =+VLOOKUP(AE42,'Mapeo Ramos'!C:D,2,0) -> Hogar | AG42: =+VLOOKUP(X42,'Mapeo Ramos'!I:J,2,0) -> HELVETIA | AH42: =+MONTH(E42) -> 1
A43: 2026000375 | B43: 7601075852 | C43: K3T300000003 | D43: 46023 | E43: 46023 | F43: 46023 | G43: TTES. AVICOLAS MANSO, S.L. | H43: HELVETIA MULTIRRIESGO TRANSPORTISTA | I43: A.MAQUINARIA | J43: 1689.28 | K43: Eur. | L43: 304.07 | M43: Eur. | N43: 304.07 | O43: Eur. | P43: 0 | Q43: Eur. | R43: ASETRA 2024 | S43: 0 | T43: Eur. | U43: Cartera | V43: Anulado_Cia | W43: BANASEG-SV | X43: HELVETIA | Y43: A.MAQUINARIA | Z43: Correduría | AA43: 47008 | AB43: VALLADOLID VALLADOLID | AC43: Empresa | AD43: B-47333042 | AE43: =+VLOOKUP(H43,'Mapeo Ramos'!A:C,3,0) -> Transportes Mercancías | AF43: =+VLOOKUP(AE43,'Mapeo Ramos'!C:D,2,0) -> Transporte | AG43: =+VLOOKUP(X43,'Mapeo Ramos'!I:J,2,0) -> HELVETIA | AH43: =+MONTH(E43) -> 1
A44: 2026000414 | B44: 7601075890 | C44: K3T300000071 | D44: 46023 | E44: 46023 | F44: 46023 | G44: TTES. AVICOLAS MANSO, S.L. | H44: HELVETIA MULTIRRIESGO TRANSPORTISTA | I44: A.MAQUINARIA | J44: 31.47 | K44: Eur. | L44: 5.67 | M44: Eur. | N44: 5.67 | O44: Eur. | P44: 0 | Q44: Eur. | R44: ASETRA 2024 | S44: 0 | T44: Eur. | U44: Cartera | V44: Anulado_Cia | W44: BANASEG-SV | X44: HELVETIA | Y44: A.MAQUINARIA | Z44: Correduría | AA44: 47008 | AB44: VALLADOLID VALLADOLID | AC44: Empresa | AD44: B-47333042 | AE44: =+VLOOKUP(H44,'Mapeo Ramos'!A:C,3,0) -> Transportes Mercancías | AF44: =+VLOOKUP(AE44,'Mapeo Ramos'!C:D,2,0) -> Transporte | AG44: =+VLOOKUP(X44,'Mapeo Ramos'!I:J,2,0) -> HELVETIA | AH44: =+MONTH(E44) -> 1
A45: 2026000416 | B45: 7601075891 | C45: K3T300000072 | D45: 46023 | E45: 46023 | F45: 46023 | G45: TTES. AVICOLAS MANSO, S.L. | H45: HELVETIA MULTIRRIESGO TRANSPORTISTA | I45: A.MAQUINARIA | J45: 1616.81 | K45: Eur. | L45: 291.02 | M45: Eur. | N45: 291.02 | O45: Eur. | P45: 0 | Q45: Eur. | R45: ASETRA 2024 | S45: 0 | T45: Eur. | U45: Cartera | V45: Anulado_Cia | W45: BANASEG-SV | X45: HELVETIA | Y45: A.MAQUINARIA | Z45: Correduría | AA45: 47008 | AB45: VALLADOLID VALLADOLID | AC45: Empresa | AD45: B-47333042 | AE45: =+VLOOKUP(H45,'Mapeo Ramos'!A:C,3,0) -> Transportes Mercancías | AF45: =+VLOOKUP(AE45,'Mapeo Ramos'!C:D,2,0) -> Transporte | AG45: =+VLOOKUP(X45,'Mapeo Ramos'!I:J,2,0) -> HELVETIA | AH45: =+MONTH(E45) -> 1
A46: 2026001664 | B46: 580586455 | C46: 12070250-02535 | D46: 46023 | E46: 46023 | F46: 46023 | G46: D-CUATRO 2014 TRANSPORTES,S.L. , | H46: ALLIANZ AUTO V. 08 COLECTIVO | I46: AUTO FLOTA | J46: 432.97 | K46: Eur. | L46: 51.96 | M46: Eur. | N46: 51.96 | O46: Eur. | P46: 0 | Q46: Eur. | S46: 0,00 | T46: Eur. | U46: Cartera | V46: Anulado_Cia | W46: BANASEG-SV | X46: ALLIANZ | Y46: AUTOS | Z46: Correduría | AA46: 40260 | AB46: FUENTEPELAYO SEGOVIA | AC46: Empresa | AD46: B-40256240 | AE46: =+VLOOKUP(H46,'Mapeo Ramos'!A:C,3,0) -> Autos Flotas | AF46: =+VLOOKUP(AE46,'Mapeo Ramos'!C:D,2,0) -> Flotas | AG46: =+VLOOKUP(X46,'Mapeo Ramos'!I:J,2,0) -> ALLIANZ | AH46: =+MONTH(E46) -> 1
A47: 2026001756 | B47: 580586257 | C47: 12070250-02366 | D47: 46023 | E47: 46023 | F47: 46023 | G47: ALFREDO MATE FRAILE | H47: ALLIANZ AUTO V. 08 COLECTIVO | I47: AUTO FLOTA | J47: 605.8 | K47: Eur. | L47: 72.7 | M47: Eur. | N47: 72.7 | O47: Eur. | P47: 0 | Q47: Eur. | S47: 0,00 | T47: Eur. | U47: Cartera | V47: Anulado_Cia | W47: BANASEG-SV | X47: ALLIANZ | Y47: AUTOS | Z47: Correduría | AA47: 34004 | AB47: PALENCIA PALENCIA | AC47: Particular | AD47: 12729153-X | AE47: =+VLOOKUP(H47,'Mapeo Ramos'!A:C,3,0) -> Autos Flotas | AF47: =+VLOOKUP(AE47,'Mapeo Ramos'!C:D,2,0) -> Flotas | AG47: =+VLOOKUP(X47,'Mapeo Ramos'!I:J,2,0) -> ALLIANZ | AH47: =+MONTH(E47) -> 1
A48: 2026001787 | B48: 580586596 | C48: 12070250-02593 | D48: 46023 | E48: 46023 | F48: 46023 | G48: TEODORO MARTIN DIAZ | H48: ALLIANZ AUTO V. 08 COLECTIVO | I48: AUTO FLOTA | J48: 214.07 | K48: Eur. | L48: 25.69 | M48: Eur. | N48: 25.69 | O48: Eur. | P48: 0 | Q48: Eur. | S48: 0,00 | T48: Eur. | U48: Cartera | V48: Anulado_Cia | W48: BANASEG-SV | X48: ALLIANZ | Y48: AUTOS | Z48: Correduría | AA48: 28223 | AB48: POZUELO DE ALARCON MADRID | AC48: Particular | AD48: 02082290-P | AE48: =+VLOOKUP(H48,'Mapeo Ramos'!A:C,3,0) -> Autos Flotas | AF48: =+VLOOKUP(AE48,'Mapeo Ramos'!C:D,2,0) -> Flotas | AG48: =+VLOOKUP(X48,'Mapeo Ramos'!I:J,2,0) -> ALLIANZ | AH48: =+MONTH(E48) -> 1
A49: 2026001788 | B49: 580586604 | C49: 12070250-02595 | D49: 46023 | E49: 46023 | F49: 46023 | G49: FERNANDO ROBLES VALDIVIESO | H49: ALLIANZ AUTO V. 08 COLECTIVO | I49: AUTO FLOTA | J49: 566.1 | K49: Eur. | L49: 67.93 | M49: Eur. | N49: 67.93 | O49: Eur. | P49: 0 | Q49: Eur. | S49: 0,00 | T49: Eur. | U49: Cartera | V49: Anulado_Cia | W49: BANASEG-SV | X49: ALLIANZ | Y49: AUTOS | Z49: Correduría | AA49: 47010 | AB49: VALLADOLID VALLADOLID | AC49: Particular | AD49: 12212755-P | AE49: =+VLOOKUP(H49,'Mapeo Ramos'!A:C,3,0) -> Autos Flotas | AF49: =+VLOOKUP(AE49,'Mapeo Ramos'!C:D,2,0) -> Flotas | AG49: =+VLOOKUP(X49,'Mapeo Ramos'!I:J,2,0) -> ALLIANZ | AH49: =+MONTH(E49) -> 1
A50: 2026001809 | B50: 580586828 | C50: 12070250-02651 | D50: 46023 | E50: 46023 | F50: 46023 | G50: ELSA HERNANDEZ CHAMORRO | H50: ALLIANZ AUTO V. 08 COLECTIVO | I50: AUTO FLOTA | J50: 819.94 | K50: Eur. | L50: 98.39 | M50: Eur. | N50: 98.39 | O50: Eur. | P50: 0 | Q50: Eur. | S50: 0,00 | T50: Eur. | U50: Cartera | V50: Anulado_Cia | W50: BANASEG-SV | X50: ALLIANZ | Y50: AUTOS | Z50: Correduría | AA50: 47005 | AB50: VALLADOLID VALLADOLID | AC50: Particular | AD50: 09407321-E | AE50: =+VLOOKUP(H50,'Mapeo Ramos'!A:C,3,0) -> Autos Flotas | AF50: =+VLOOKUP(AE50,'Mapeo Ramos'!C:D,2,0) -> Flotas | AG50: =+VLOOKUP(X50,'Mapeo Ramos'!I:J,2,0) -> ALLIANZ | AH50: =+MONTH(E50) -> 1
A51: 2026001811 | B51: 580586836 | C51: 12070250-02655 | D51: 46023 | E51: 46023 | F51: 46023 | G51: CARGAS Y SERV. AVICOLAS CANARIAS, S.L. | H51: ALLIANZ AUTO TODO RIESGO V.08 COLECTIVO | I51: AUTO FLOTA | J51: 1235.76 | K51: Eur. | L51: 148.29 | M51: Eur. | N51: 148.29 | O51: Eur. | P51: 0 | Q51: Eur. | R51: ASETRA | S51: 30.89 | T51: Eur. | U51: Cartera | V51: Anulado_Cia | W51: BANASEG-SV | X51: ALLIANZ | Y51: AUTOS | Z51: Correduría | AA51: 47008 | AB51: VALLADOLID VALLADOLID | AC51: Empresa | AD51: B-76514017 | AE51: =+VLOOKUP(H51,'Mapeo Ramos'!A:C,3,0) -> Autos Flotas | AF51: =+VLOOKUP(AE51,'Mapeo Ramos'!C:D,2,0) -> Flotas | AG51: =+VLOOKUP(X51,'Mapeo Ramos'!I:J,2,0) -> ALLIANZ | AH51: =+MONTH(E51) -> 1
A52: 2026001812 | B52: 580586844 | C52: 12070250-02656 | D52: 46023 | E52: 46023 | F52: 46023 | G52: CARGAS Y SERV. AVICOLAS CANARIAS, S.L. | H52: ALLIANZ AUTO TODO RIESGO V.08 COLECTIVO | I52: AUTO FLOTA | J52: 1235.76 | K52: Eur. | L52: 148.29 | M52: Eur. | N52: 148.29 | O52: Eur. | P52: 0 | Q52: Eur. | R52: ASETRA | S52: 30.89 | T52: Eur. | U52: Cartera | V52: Anulado_Cia | W52: BANASEG-SV | X52: ALLIANZ | Y52: AUTOS | Z52: Correduría | AA52: 47008 | AB52: VALLADOLID VALLADOLID | AC52: Empresa | AD52: B-76514017 | AE52: =+VLOOKUP(H52,'Mapeo Ramos'!A:C,3,0) -> Autos Flotas | AF52: =+VLOOKUP(AE52,'Mapeo Ramos'!C:D,2,0) -> Flotas | AG52: =+VLOOKUP(X52,'Mapeo Ramos'!I:J,2,0) -> ALLIANZ | AH52: =+MONTH(E52) -> 1
A53: 2026001813 | B53: 580586851 | C53: 12070250-02657 | D53: 46023 | E53: 46023 | F53: 46023 | G53: CARGAS Y SERV. AVICOLAS CANARIAS, S.L. | H53: ALLIANZ AUTO TODO RIESGO V.08 COLECTIVO | I53: AUTO FLOTA | J53: 1235.76 | K53: Eur. | L53: 148.29 | M53: Eur. | N53: 148.29 | O53: Eur. | P53: 0 | Q53: Eur. | R53: ASETRA | S53: 30.89 | T53: Eur. | U53: Cartera | V53: Anulado_Cia | W53: BANASEG-SV | X53: ALLIANZ | Y53: AUTOS | Z53: Correduría | AA53: 47008 | AB53: VALLADOLID VALLADOLID | AC53: Empresa | AD53: B-76514017 | AE53: =+VLOOKUP(H53,'Mapeo Ramos'!A:C,3,0) -> Autos Flotas | AF53: =+VLOOKUP(AE53,'Mapeo Ramos'!C:D,2,0) -> Flotas | AG53: =+VLOOKUP(X53,'Mapeo Ramos'!I:J,2,0) -> ALLIANZ | AH53: =+MONTH(E53) -> 1
A54: 2026001815 | B54: 580586877 | C54: 12070250-02659 | D54: 46023 | E54: 46023 | F54: 46023 | G54: CARGAS Y SERV. AVICOLAS CANARIAS, S.L. | H54: ALLIANZ AUTO TODO RIESGO V.08 COLECTIVO | I54: AUTO FLOTA | J54: 1235.76 | K54: Eur. | L54: 148.29 | M54: Eur. | N54: 148.29 | O54: Eur. | P54: 0 | Q54: Eur. | R54: ASETRA | S54: 30.89 | T54: Eur. | U54: Cartera | V54: Anulado_Cia | W54: BANASEG-SV | X54: ALLIANZ | Y54: AUTOS | Z54: Correduría | AA54: 47008 | AB54: VALLADOLID VALLADOLID | AC54: Empresa | AD54: B-76514017 | AE54: =+VLOOKUP(H54,'Mapeo Ramos'!A:C,3,0) -> Autos Flotas | AF54: =+VLOOKUP(AE54,'Mapeo Ramos'!C:D,2,0) -> Flotas | AG54: =+VLOOKUP(X54,'Mapeo Ramos'!I:J,2,0) -> ALLIANZ | AH54: =+MONTH(E54) -> 1
A55: 2026000900 | B55: 580588550 | C55: 12372022-01249 | D55: 46023 | E55: 46023 | F55: 46023 | G55: ESHREF ALIEV DZHAVIDOV | H55: AUTOGRUP V.03 (VH.COM. 2ª CATEG.) | I55: AUTO FLOTA | J55: 400.86 | K55: Eur. | L55: 48.1 | M55: Eur. | N55: 48.1 | O55: Eur. | P55: 0 | Q55: Eur. | S55: 0,00 | T55: Eur. | U55: Cartera | V55: Anulado_Cia | W55: BANASEG-SV | X55: ALLIANZ | Y55: AUTOS | Z55: Correduría | AA55: 47151 | AB55: BOECILLO VALLADOLID | AC55: Particular | AD55: X5527367-F | AE55: =+VLOOKUP(H55,'Mapeo Ramos'!A:C,3,0) -> Autos Flotas | AF55: =+VLOOKUP(AE55,'Mapeo Ramos'!C:D,2,0) -> Flotas | AG55: =+VLOOKUP(X55,'Mapeo Ramos'!I:J,2,0) -> ALLIANZ | AH55: =+MONTH(E55) -> 1
A56: 2026000902 | B56: 580588600 | C56: 12372022-01263 | D56: 46023 | E56: 46023 | F56: 46023 | G56: PRISCO E HIJO S.L. , | H56: AUTOGRUP V.03 (VH.COM. 2ª CATEG.) | I56: AUTO FLOTA | J56: 400.86 | K56: Eur. | L56: 48.1 | M56: Eur. | N56: 48.1 | O56: Eur. | P56: 0 | Q56: Eur. | R56: ASETRA | S56: 10.02 | T56: Eur. | U56: Cartera | V56: Anulado_Cia | W56: BANASEG-SV | X56: ALLIANZ | Y56: AUTOS | Z56: Correduría | AA56: 47013 | AB56: VALLADOLID VALLADOLID | AC56: Empresa | AD56: B-47787197 | AE56: =+VLOOKUP(H56,'Mapeo Ramos'!A:C,3,0) -> Autos Flotas | AF56: =+VLOOKUP(AE56,'Mapeo Ramos'!C:D,2,0) -> Flotas | AG56: =+VLOOKUP(X56,'Mapeo Ramos'!I:J,2,0) -> ALLIANZ | AH56: =+MONTH(E56) -> 1
A57: 2026000944 | B57: 580589038 | C57: 12372022-01455 | D57: 46023 | E57: 46023 | F57: 46023 | G57: PRISCO E HIJO S.L. , | H57: AUTOGRUP V.03 (VH.COM. 2ª CATEG.) | I57: AUTO FLOTA | J57: 947.12 | K57: Eur. | L57: 113.65 | M57: Eur. | N57: 113.65 | O57: Eur. | P57: 0 | Q57: Eur. | R57: ASETRA | S57: 23.68 | T57: Eur. | U57: Cartera | V57: Anulado_Cia | W57: BANASEG-SV | X57: ALLIANZ | Y57: AUTOS | Z57: Correduría | AA57: 47013 | AB57: VALLADOLID VALLADOLID | AC57: Empresa | AD57: B-47787197 | AE57: =+VLOOKUP(H57,'Mapeo Ramos'!A:C,3,0) -> Autos Flotas | AF57: =+VLOOKUP(AE57,'Mapeo Ramos'!C:D,2,0) -> Flotas | AG57: =+VLOOKUP(X57,'Mapeo Ramos'!I:J,2,0) -> ALLIANZ | AH57: =+MONTH(E57) -> 1
A58: 2026000950 | B58: 580589103 | C58: 12372022-01476 | D58: 46023 | E58: 46023 | F58: 46023 | G58: PRISCO E HIJO S.L. , | H58: AUTOGRUP V.03 (VH.COM. 2ª CATEG.) | I58: AUTO FLOTA | J58: 991.05 | K58: Eur. | L58: 118.93 | M58: Eur. | N58: 118.93 | O58: Eur. | P58: 0 | Q58: Eur. | R58: ASETRA | S58: 24.78 | T58: Eur. | U58: Cartera | V58: Anulado_Cia | W58: BANASEG-SV | X58: ALLIANZ | Y58: AUTOS | Z58: Correduría | AA58: 47013 | AB58: VALLADOLID VALLADOLID | AC58: Empresa | AD58: B-47787197 | AE58: =+VLOOKUP(H58,'Mapeo Ramos'!A:C,3,0) -> Autos Flotas | AF58: =+VLOOKUP(AE58,'Mapeo Ramos'!C:D,2,0) -> Flotas | AG58: =+VLOOKUP(X58,'Mapeo Ramos'!I:J,2,0) -> ALLIANZ | AH58: =+MONTH(E58) -> 1
A59: 2026000965 | B59: 580589236 | C59: 12372022-01534 | D59: 46023 | E59: 46023 | F59: 46023 | G59: PRISCO E HIJO S.L. , | H59: AUTOGRUP V.03 (VH.COM. 2ª CATEG.) | I59: AUTO FLOTA | J59: 2979.91 | K59: Eur. | L59: 357.59 | M59: Eur. | N59: 357.59 | O59: Eur. | P59: 0 | Q59: Eur. | R59: ASETRA | S59: 74.5 | T59: Eur. | U59: Cartera | V59: Anulado_Cia | W59: BANASEG-SV | X59: ALLIANZ | Y59: AUTOS | Z59: Correduría | AA59: 47013 | AB59: VALLADOLID VALLADOLID | AC59: Empresa | AD59: B-47787197 | AE59: =+VLOOKUP(H59,'Mapeo Ramos'!A:C,3,0) -> Autos Flotas | AF59: =+VLOOKUP(AE59,'Mapeo Ramos'!C:D,2,0) -> Flotas | AG59: =+VLOOKUP(X59,'Mapeo Ramos'!I:J,2,0) -> ALLIANZ | AH59: =+MONTH(E59) -> 1
A60: 2026000853 | B60: 580589384 | C60: 12372022-01555 | D60: 46023 | E60: 46023 | F60: 46023 | G60: PIENSOS A GRANEL ANDRES,SL. , | H60: AUTOGRUP V.03 (VH.COM. 2ª CATEG.) | I60: AUTO FLOTA | J60: 2693.12 | K60: Eur. | L60: 323.17 | M60: Eur. | N60: 323.17 | O60: Eur. | P60: 0 | Q60: Eur. | R60: ASETRA | S60: 67.33 | T60: Eur. | U60: Cartera | V60: Anulado_Cia | W60: BANASEG-SV | X60: ALLIANZ | Y60: AUTOS | Z60: Correduría | AA60: 47193 | AB60: CISTERNIGA VALLADOLID | AC60: Empresa | AD60: B-47754494 | AE60: =+VLOOKUP(H60,'Mapeo Ramos'!A:C,3,0) -> Autos Flotas | AF60: =+VLOOKUP(AE60,'Mapeo Ramos'!C:D,2,0) -> Flotas | AG60: =+VLOOKUP(X60,'Mapeo Ramos'!I:J,2,0) -> ALLIANZ | AH60: =+MONTH(E60) -> 1
A61: 2026000979 | B61: 580589392 | C61: 12372022-01557 | D61: 46023 | E61: 46023 | F61: 46023 | G61: PRISCO E HIJO S.L. , | H61: AUTOGRUP V.03 (VH.COM. 2ª CATEG.) | I61: AUTO FLOTA | J61: 400.86 | K61: Eur. | L61: 48.1 | M61: Eur. | N61: 48.1 | O61: Eur. | P61: 0 | Q61: Eur. | R61: ASETRA | S61: 10.02 | T61: Eur. | U61: Cartera | V61: Anulado_Cia | W61: BANASEG-SV | X61: ALLIANZ | Y61: AUTOS | Z61: Correduría | AA61: 47013 | AB61: VALLADOLID VALLADOLID | AC61: Empresa | AD61: B-47787197 | AE61: =+VLOOKUP(H61,'Mapeo Ramos'!A:C,3,0) -> Autos Flotas | AF61: =+VLOOKUP(AE61,'Mapeo Ramos'!C:D,2,0) -> Flotas | AG61: =+VLOOKUP(X61,'Mapeo Ramos'!I:J,2,0) -> ALLIANZ | AH61: =+MONTH(E61) -> 1
A62: 2026000993 | B62: 580589533 | C62: 12372022-01585 | D62: 46023 | E62: 46023 | F62: 46023 | G62: TTES. SABAS VALLADOLID, S.L. | H62: AUTOGRUP V.03 (VH.COM. 2ª CATEG.) | I62: AUTO FLOTA | J62: 1259.09 | K62: Eur. | L62: 151.09 | M62: Eur. | N62: 151.09 | O62: Eur. | P62: 0 | Q62: Eur. | S62: 0,00 | T62: Eur. | U62: Cartera | V62: Anulado_Cia | W62: BANASEG-SV | X62: ALLIANZ | Y62: AUTOS | Z62: Correduría | AA62: 47151 | AB62: BOECILLO VALLADOLID | AC62: Empresa | AD62: B-47634407 | AE62: =+VLOOKUP(H62,'Mapeo Ramos'!A:C,3,0) -> Autos Flotas | AF62: =+VLOOKUP(AE62,'Mapeo Ramos'!C:D,2,0) -> Flotas | AG62: =+VLOOKUP(X62,'Mapeo Ramos'!I:J,2,0) -> ALLIANZ | AH62: =+MONTH(E62) -> 1
A63: 2026000996 | B63: 580589574 | C63: 12372022-01593 | D63: 46023 | E63: 46023 | F63: 46023 | G63: JOSE MARIA DEL CAÑO MONEDERO | H63: AUTOGRUP V.03 (VH.COM. 2ª CATEG.) | I63: AUTO FLOTA | J63: 1259.09 | K63: Eur. | L63: 151.09 | M63: Eur. | N63: 151.09 | O63: Eur. | P63: 0 | Q63: Eur. | S63: 0,00 | T63: Eur. | U63: Cartera | V63: Anulado_Cia | W63: BANASEG-SV | X63: ALLIANZ | Y63: AUTOS | Z63: Correduría | AA63: 40219 | AB63: VILLAVERDE DE ISCAR SEGOVIA | AC63: Particular | AD63: 03452175-J | AE63: =+VLOOKUP(H63,'Mapeo Ramos'!A:C,3,0) -> Autos Flotas | AF63: =+VLOOKUP(AE63,'Mapeo Ramos'!C:D,2,0) -> Flotas | AG63: =+VLOOKUP(X63,'Mapeo Ramos'!I:J,2,0) -> ALLIANZ | AH63: =+MONTH(E63) -> 1
...

Sheet Mapeo Ramos
A1: Producto | B1: Ramo | C1: Equivalencia 08/2025 | D1: Equivalencia
A2: 1216-ALLIANZ PATINETE | B2: AUTOS | C2: Autos Cat. 3 | D2: Autos | I2: MAPFRE ESPAÑA, S.A. | J2: MAPFRE
A3: 43 - ARAG NEGOCIO FLEXIBLE | B3: P.JURIDICA | C3: Defensa Jurídica | D3: Particulares Resto | I3: ALLIANZ | J3: ALLIANZ
A4: ACC. BAJA DIARIA | C4: Accidentes Convenio | D4: Seguros Personales (No Vida) Colectivos | I4: OCCIDENT GCO, S.A.U. DE SEGUROS Y REASEGUROS | J4: OCCIDENT
A5: ACC. COLECTIVO | B5: ACCIDENTES | C5: Accidentes Colectivo | D5: Seguros Personales (No Vida) Colectivos | I5: ESPABROK | J5: ESPABROK
A6: ACC. COLECTIVO GR | C6: Accidentes Colectivo | D6: Seguros Personales (No Vida) Colectivos | I6: MARKEL INSURANCE SE | J6: MARKEL
A7: ACC. COLECTIVOS EMPRESAS | C7: Accidentes Colectivo | D7: Seguros Personales (No Vida) Colectivos | I7: ARAG S.E. | J7: ARAG
A8: ACC. CONVENIO | B8: ACCIDENTES | C8: Accidentes Convenio | D8: Seguros Personales (No Vida) Colectivos | I8: AXA SEG.GNRALES | J8: AXA
A9: ACC. CONVENIO G.R | B9: ACCIDENTES | C9: Accidentes Convenio | D9: Seguros Personales (No Vida) Colectivos | I9: FIATC | J9: FIATC
A10: ACCID. INDIVID. 2006 | C10: Accidentes Individual | D10: Seguros Personales (No Vida) Particular | I10: GENERALI ESPAÑA | J10: GENERALI
A11: ACCIDENTE INDIVIDUAL | B11: ACCIDENTES | C11: Accidentes Individual | D11: Seguros Personales (No Vida) Particular | I11: REALE | J11: REALE
A12: ACCIDENTES | C12: Accidentes Individual | D12: Seguros Personales (No Vida) Particular | I12: HELVETIA | J12: HELVETIA
A13: ACCIDENTES | C13: Accidentes Individual | D13: Seguros Personales (No Vida) Particular | I13: CASER SEGUROS | J13: CASER
A14: ACCIDENTES COLECTIVO | B14: ACCIDENTES | C14: Accidentes Colectivo | D14: Seguros Personales (No Vida) Colectivos | I14: ASEFA | J14: ASEFA
A15: ACCIDENTES COLECTIVOS | B15: ACCIDENTES | C15: Accidentes Colectivo | D15: Seguros Personales (No Vida) Colectivos | I15: AIG EUROPE, S.A. SUCURSAL EN ESPAÑA | J15: AIG
A16: ACCIDENTES CONVENIO | B16: ACCIDENTES | C16: Accidentes Convenio | D16: Seguros Personales (No Vida) Colectivos | I16: SANITAS | J16: SANITAS
A17: ACCIDENTES CONVENIO COLECTIVO | B17: ACCIDENTES | C17: Accidentes Convenio | D17: Seguros Personales (No Vida) Colectivos | I17: ASISA | J17: ASISA
A18: ACCIDENTES CONVENIO PYME | B18: ACCIDENTES | C18: Accidentes Convenio | D18: Seguros Personales (No Vida) Colectivos | I18: ZURICH INSURANCE | J18: ZURICH
A19: ACCIDENTES INDIVIDUAL | B19: ACCIDENTES | C19: Accidentes Individual | D19: Seguros Personales (No Vida) Particular | I19: DKV | J19: DKV
A20: ACCIDENTES INDIVIDUALES | C20: Accidentes Individual | D20: Seguros Personales (No Vida) Particular | I20: ADESLAS | J20: SEGURCAIXA ADESLAS
A21: ACTIVIDADES EMPRESARIALES | B21: M. INDUSTRIAL | C21: Multirriesgo Industriales (PYME) | D21: Property | I21: SURNE | J21: SVRNE
A22: AGRARIA GENERICA - EXPLOTACIONES Y GRANJAS | C22: Multirriesgo Industriales (PYME) | D22: Property | I22: VIDA CAIXA | J22: SEGURCAIXA ADESLAS
A23: AGRICOLA/REMOLQUES/CAMIONES | B23: AUTOS | C23: Autos Cat. 2 | D23: Flotas | I23: MUTUA DE PROPIETARIOS | J23: MUTUA PROPIETARIOS
A24: AGROCASER EXPLOTACIONES AGROPECUARIAS | B24: M. INDUSTRIAL | C24: Otros Multirriesgo | D24: Property | I24: CATALANA-OCCIDENTE | J24: OCCIDENT
A25: AHORRO | C25: Vida Ahorro Individual | D25: Vida Ahorro Particular | I25: SANTA LUCIA VIDA Y PENSIONES, SA | J25: SANTA LUCIA
A26: AHORRO | C26: Vida Ahorro Individual | D26: Vida Ahorro Particular | I26: MUTUA MADRILEÑA AUTOMOVILISTA SSPF | J26: MUTUA MADRILEÑA
A27: AHORRO SEGURO | B27: AHORRO | C27: Vida Ahorro Individual | D27: Vida Ahorro Particular | I27: LIBERTY SEGUROS | J27: GENERALI
A28: ALL AUTO | B28: AUTOS | C28: Autos Cat. 1 | D28: Autos | I28: HDI GERLING | J28: HDI
A29: ALL. COMERCIAL | B29: AUTOS | C29: Autos Cat. 1 | D29: Autos | I29: LA PREVISION MALLORQUINA DE SEGUROS, S.A. | J29: PREVISIÓN MALLORQUINA
A30: ALL.COMUNIDADES | B30: M.COMUNIDADES | C30: Comunidades | D30: Property | I30: SOLUNION | J30: SOLUNION
A31: ALLIAN HOGAR | B31: M.HOGAR | C31: Hogar | D31: Hogar | I31: DAS DEFENSA | J31: ONLYGAL
A32: ALLIANZ ACCIDENTES v05 | B32: ACCIDENTES | C32: Accidentes Individual | D32: Seguros Personales (No Vida) Particular | I32: GENERALI SEGUROS Y REASEGUROS, S.A.U. | J32: GENERALI
A33: ALLIANZ AUTO BASICO v.05 | B33: AUTOS | C33: Autos Cat. 1 | D33: Autos | I33: G. SANCHEZ-VALENCIA | J33: NO IDENTIFICADO
A34: ALLIANZ AUTO DAÑOS v.05 | B34: AUTOS | C34: Autos Cat. 1 | D34: Autos | I34: BRUJULA ASESORES S.L | J34: BRUJULA
A35: ALLIANZ AUTO PLUS | B35: AUTOS | C35: Autos Cat. 1 | D35: Autos | I35: BERKLEY | J35: BERKLEY
A36: ALLIANZ AUTO PLUS TODO RIESGO | B36: AUTOS | C36: Autos Cat. 1 | D36: Autos | I36: HISCOX | J36: HISCOX
A37: ALLIANZ AUTO TERCEROS | B37: AUTOS | C37: Autos Cat. 1 | D37: Autos | I37: MIC INSURANCE | J37: MIC INSURANCE
A38: ALLIANZ AUTO TERCEROS COLECTIVO | B38: AUTOS FLOTA | C38: Autos Flotas | D38: Flotas | I38: MUSSAP | J38: MUSSAP
... A40: ALLIANZ AUTO TODO RIESGO V.08 | B40: AUTOS | C40: Autos Cat. 1 | D40: Autos | I40: GENERALI ESPAÑA de Seguros y Reaseguros, S.A. | J40: GENERALI
A41: ALLIANZ AUTO TODO RIESGO V.08 COLECTIVO | B41: AUTO FLOTA | C41: Autos Flotas | D41: Flotas
...
